Workbook
Name Print_Area_MI: 'MANHOLES (1)'!$V$53:$IU$1804
Name Print_Area_MI: 'MANHOLES (2)'!$V$53:$IU$1804
Name Print_Area_MI: 'MANHOLES (3)'!$V$64:$IU$1815
Name Print_Area_MI: 'SEWERS (1)'!$A$3:$AB$75
Name Print_Area_MI: 'SEWERS (2)'!$A$3:$AB$75
Name Print_Area_MI: 'SEWERS (3)'!$A$3:$AB$75
Name Print_Area_MI: 'SEWERS (4)'!$A$3:$AB$75
Name Print_Area_MI: 'WATERMAIN (1)'!$Y$85:$IU$1817
Name Print_Area_MI: 'WATERMAIN (2)'!$Y$85:$IU$1817
Name Print_Titles_MI: 'MANHOLES (1)'!$1804:$65536
Name Print_Titles_MI: 'MANHOLES (2)'!$1804:$65536
Name Print_Titles_MI: 'MANHOLES (3)'!$1815:$65536
Name Print_Titles_MI: 'WATERMAIN (1)'!$3:$1817
Name Print_Titles_MI: 'WATERMAIN (2)'!$3:$1817

Sheet MANHOLES (1)
A1: TOPSITE CONTRACTING LIMITED - MANHOLE & CATCHBASIN ESTIMATE 2022
A3: JOB: | D3: $/CM TRUCKING | F3: 10 | H3: FSTfctr | I3: 1
D4: $/CM CONCRETE | F4: 250 | H4: PSTfct | I4: 1 | K4: LABOR/HR | L4: 110 | O4: =IF(F7=1,"METRIC","IMPERIAL") -> METRIC | P4: =O4 -> METRIC | Q4: =O4 -> METRIC
A5: DATE: | D5: %DISCOUNT | F5: 40 | H5: Mod$/m | I5: 718
D6: MARGIN FACTOR | F6: 1.1 | H6: MH F&C $ | I6: 375 | K6: DSC/TX FCTR | L6: 1 | U6: REVISED: | V6: 44859
C7: =O4 -> METRIC | D7: METRIC 1/ IMPER 0 | F7: 1 | H7: CB F&C $ | I7: 500 | K7: FR+CVR m | L7: 0.3 | U7: PRINTED: | V7: =TODAY() -> 46143
A9: Item | B9: MH Description | C9: Top El. | D9: Low Inv | E9: Hi Inv | F9: Pipe Out | G9: ST1/L2 | H9: Add$Mtrls | I9: Add$L&E | J9: Depth m | K9: Drop m | L9: MHdia-mm | M9: PCovrall | N9: $Precast | O9: $Conc | P9: $Fr&Cov | Q9: $Matrl | R9: $L&E | S9: $Trkng | T9: $/VM | U9: TOTAL $ | V9: SALE$
A10: 0
A11: 1 | J11: =(C11-D11)*IF(F$7=1,1,0.3049) -> 0 | K11: =IF(E11=0,0,(D11-E11)*IF(F$7=1,1,0.3049)) -> 0 | L11: =IF(F11=0,0,IF((G11=1),HLOOKUP(F11,B$65:F$66,2),HLOOKUP(F11,H$65:L$66,2))) -> 0 | M11: =IF(J11=0,0,J11-L$7+0.3*F11/1000+0.3) -> 0 | N11: =(IF(L11=0,0,IF(L11<1501,VLOOKUP(L11+M11,C$70:D$118,2),VLOOKUP(L11+M11,E$70:F$114,2))+(L$7-0.15)*I$5)*I$3*I$4*(100-F$5)/100) -> 0 | O11: =(((L11/1000)^2*PI()/4*F11/1000)-PI()/4*(F11/1000)^2*L11/1000+L11/1000)*F$4 -> 0 | P11: =IF(L11=0,0,I$6*I$3*I$4) -> 0 | Q11: =H11+N11+O11+P11 -> 0 | R11: =(L11=1200)*(15*L$4+L$4*M11)+(L11=1500)*(20*L$4+1.3*L$4*M11)+(L11=1800)*(30*L$4+1.5*L$4*M11)+(L11=2400)*(40*L$4+2*L$4*M11)+(L11=3000)*(50*L$4+2.5*L$4*M11)+(L11=3600)*(60*L$4+3*L$4*M11)+I11 -> 0 | S11: =F$3*(J11*(0.001*L11*1.3)^2*PI()/4) -> 0 | T11: =IF(L11=0,0,(Q11+R11+S11)/J11) -> 0 | U11: =Q11+R11+S11 -> 0 | V11: =U11*F$6 -> 0
A12: 2 | J12: =(C12-D12)*IF(F$7=1,1,0.3049) -> 0 | K12: =IF(E12=0,0,(D12-E12)*IF(F$7=1,1,0.3049)) -> 0 | L12: =IF(F12=0,0,IF((G12=1),HLOOKUP(F12,B$65:F$66,2),HLOOKUP(F12,H$65:L$66,2))) -> 0 | M12: =IF(J12=0,0,J12-L$7+0.3*F12/1000+0.3) -> 0 | N12: =(IF(L12=0,0,IF(L12<1501,VLOOKUP(L12+M12,C$70:D$118,2),VLOOKUP(L12+M12,E$70:F$114,2))+(L$7-0.15)*I$5)*I$3*I$4*(100-F$5)/100) -> 0 | O12: =(((L12/1000)^2*PI()/4*F12/1000)-PI()/4*(F12/1000)^2*L12/1000+L12/1000)*F$4 -> 0 | P12: =IF(L12=0,0,I$6*I$3*I$4) -> 0 | Q12: =H12+N12+O12+P12 -> 0 | R12: =(L12=1200)*(15*L$4+L$4*M12)+(L12=1500)*(20*L$4+1.3*L$4*M12)+(L12=1800)*(30*L$4+1.5*L$4*M12)+(L12=2400)*(40*L$4+2*L$4*M12)+(L12=3000)*(50*L$4+2.5*L$4*M12)+(L12=3600)*(60*L$4+3*L$4*M12)+I12 -> 0 | S12: =F$3*(J12*(0.001*L12*1.3)^2*PI()/4) -> 0 | T12: =IF(L12=0,0,(Q12+R12+S12)/J12) -> 0 | U12: =Q12+R12+S12 -> 0 | V12: =U12*F$6 -> 0
A13: 3 | J13: =(C13-D13)*IF(F$7=1,1,0.3049) -> 0 | K13: =IF(E13=0,0,(D13-E13)*IF(F$7=1,1,0.3049)) -> 0 | L13: =IF(F13=0,0,IF((G13=1),HLOOKUP(F13,B$65:F$66,2),HLOOKUP(F13,H$65:L$66,2))) -> 0 | M13: =IF(J13=0,0,J13-L$7+0.3*F13/1000+0.3) -> 0 | N13: =(IF(L13=0,0,IF(L13<1501,VLOOKUP(L13+M13,C$70:D$118,2),VLOOKUP(L13+M13,E$70:F$114,2))+(L$7-0.15)*I$5)*I$3*I$4*(100-F$5)/100) -> 0 | O13: =(((L13/1000)^2*PI()/4*F13/1000)-PI()/4*(F13/1000)^2*L13/1000+L13/1000)*F$4 -> 0 | P13: =IF(L13=0,0,I$6*I$3*I$4) -> 0 | Q13: =H13+N13+O13+P13 -> 0 | R13: =(L13=1200)*(15*L$4+L$4*M13)+(L13=1500)*(20*L$4+1.3*L$4*M13)+(L13=1800)*(30*L$4+1.5*L$4*M13)+(L13=2400)*(40*L$4+2*L$4*M13)+(L13=3000)*(50*L$4+2.5*L$4*M13)+(L13=3600)*(60*L$4+3*L$4*M13)+I13 -> 0 | S13: =F$3*(J13*(0.001*L13*1.3)^2*PI()/4) -> 0 | T13: =IF(L13=0,0,(Q13+R13+S13)/J13) -> 0 | U13: =Q13+R13+S13 -> 0 | V13: =U13*F$6 -> 0
A14: 4 | J14: =(C14-D14)*IF(F$7=1,1,0.3049) -> 0 | K14: =IF(E14=0,0,(D14-E14)*IF(F$7=1,1,0.3049)) -> 0 | L14: =IF(F14=0,0,IF((G14=1),HLOOKUP(F14,B$65:F$66,2),HLOOKUP(F14,H$65:L$66,2))) -> 0 | M14: =IF(J14=0,0,J14-L$7+0.3*F14/1000+0.3) -> 0 | N14: =(IF(L14=0,0,IF(L14<1501,VLOOKUP(L14+M14,C$70:D$118,2),VLOOKUP(L14+M14,E$70:F$114,2))+(L$7-0.15)*I$5)*I$3*I$4*(100-F$5)/100) -> 0 | O14: =(((L14/1000)^2*PI()/4*F14/1000)-PI()/4*(F14/1000)^2*L14/1000+L14/1000)*F$4 -> 0 | P14: =IF(L14=0,0,I$6*I$3*I$4) -> 0 | Q14: =H14+N14+O14+P14 -> 0 | R14: =(L14=1200)*(15*L$4+L$4*M14)+(L14=1500)*(20*L$4+1.3*L$4*M14)+(L14=1800)*(30*L$4+1.5*L$4*M14)+(L14=2400)*(40*L$4+2*L$4*M14)+(L14=3000)*(50*L$4+2.5*L$4*M14)+(L14=3600)*(60*L$4+3*L$4*M14)+I14 -> 0 | S14: =F$3*(J14*(0.001*L14*1.3)^2*PI()/4) -> 0 | T14: =IF(L14=0,0,(Q14+R14+S14)/J14) -> 0 | U14: =Q14+R14+S14 -> 0 | V14: =U14*F$6 -> 0
A15: 5 | J15: =(C15-D15)*IF(F$7=1,1,0.3049) -> 0 | K15: =IF(E15=0,0,(D15-E15)*IF(F$7=1,1,0.3049)) -> 0 | L15: =IF(F15=0,0,IF((G15=1),HLOOKUP(F15,B$65:F$66,2),HLOOKUP(F15,H$65:L$66,2))) -> 0 | M15: =IF(J15=0,0,J15-L$7+0.3*F15/1000+0.3) -> 0 | N15: =(IF(L15=0,0,IF(L15<1501,VLOOKUP(L15+M15,C$70:D$118,2),VLOOKUP(L15+M15,E$70:F$114,2))+(L$7-0.15)*I$5)*I$3*I$4*(100-F$5)/100) -> 0 | O15: =(((L15/1000)^2*PI()/4*F15/1000)-PI()/4*(F15/1000)^2*L15/1000+L15/1000)*F$4 -> 0 | P15: =IF(L15=0,0,I$6*I$3*I$4) -> 0 | Q15: =H15+N15+O15+P15 -> 0 | R15: =(L15=1200)*(15*L$4+L$4*M15)+(L15=1500)*(20*L$4+1.3*L$4*M15)+(L15=1800)*(30*L$4+1.5*L$4*M15)+(L15=2400)*(40*L$4+2*L$4*M15)+(L15=3000)*(50*L$4+2.5*L$4*M15)+(L15=3600)*(60*L$4+3*L$4*M15)+I15 -> 0 | S15: =F$3*(J15*(0.001*L15*1.3)^2*PI()/4) -> 0 | T15: =IF(L15=0,0,(Q15+R15+S15)/J15) -> 0 | U15: =Q15+R15+S15 -> 0 | V15: =U15*F$6 -> 0
A16: 6 | J16: =(C16-D16)*IF(F$7=1,1,0.3049) -> 0 | K16: =IF(E16=0,0,(D16-E16)*IF(F$7=1,1,0.3049)) -> 0 | L16: =IF(F16=0,0,IF((G16=1),HLOOKUP(F16,B$65:F$66,2),HLOOKUP(F16,H$65:L$66,2))) -> 0 | M16: =IF(J16=0,0,J16-L$7+0.3*F16/1000+0.3) -> 0 | N16: =(IF(L16=0,0,IF(L16<1501,VLOOKUP(L16+M16,C$70:D$118,2),VLOOKUP(L16+M16,E$70:F$114,2))+(L$7-0.15)*I$5)*I$3*I$4*(100-F$5)/100) -> 0 | O16: =(((L16/1000)^2*PI()/4*F16/1000)-PI()/4*(F16/1000)^2*L16/1000+L16/1000)*F$4 -> 0 | P16: =IF(L16=0,0,I$6*I$3*I$4) -> 0 | Q16: =H16+N16+O16+P16 -> 0 | R16: =(L16=1200)*(15*L$4+L$4*M16)+(L16=1500)*(20*L$4+1.3*L$4*M16)+(L16=1800)*(30*L$4+1.5*L$4*M16)+(L16=2400)*(40*L$4+2*L$4*M16)+(L16=3000)*(50*L$4+2.5*L$4*M16)+(L16=3600)*(60*L$4+3*L$4*M16)+I16 -> 0 | S16: =F$3*(J16*(0.001*L16*1.3)^2*PI()/4) -> 0 | T16: =IF(L16=0,0,(Q16+R16+S16)/J16) -> 0 | U16: =Q16+R16+S16 -> 0 | V16: =U16*F$6 -> 0
A17: 7 | J17: =(C17-D17)*IF(F$7=1,1,0.3049) -> 0 | K17: =IF(E17=0,0,(D17-E17)*IF(F$7=1,1,0.3049)) -> 0 | L17: =IF(F17=0,0,IF((G17=1),HLOOKUP(F17,B$65:F$66,2),HLOOKUP(F17,H$65:L$66,2))) -> 0 | M17: =IF(J17=0,0,J17-L$7+0.3*F17/1000+0.3) -> 0 | N17: =(IF(L17=0,0,IF(L17<1501,VLOOKUP(L17+M17,C$70:D$118,2),VLOOKUP(L17+M17,E$70:F$114,2))+(L$7-0.15)*I$5)*I$3*I$4*(100-F$5)/100) -> 0 | O17: =(((L17/1000)^2*PI()/4*F17/1000)-PI()/4*(F17/1000)^2*L17/1000+L17/1000)*F$4 -> 0 | P17: =IF(L17=0,0,I$6*I$3*I$4) -> 0 | Q17: =H17+N17+O17+P17 -> 0 | R17: =(L17=1200)*(15*L$4+L$4*M17)+(L17=1500)*(20*L$4+1.3*L$4*M17)+(L17=1800)*(30*L$4+1.5*L$4*M17)+(L17=2400)*(40*L$4+2*L$4*M17)+(L17=3000)*(50*L$4+2.5*L$4*M17)+(L17=3600)*(60*L$4+3*L$4*M17)+I17 -> 0 | S17: =F$3*(J17*(0.001*L17*1.3)^2*PI()/4) -> 0 | T17: =IF(L17=0,0,(Q17+R17+S17)/J17) -> 0 | U17: =Q17+R17+S17 -> 0 | V17: =U17*F$6 -> 0
A18: 8 | J18: =(C18-D18)*IF(F$7=1,1,0.3049) -> 0 | K18: =IF(E18=0,0,(D18-E18)*IF(F$7=1,1,0.3049)) -> 0 | L18: =IF(F18=0,0,IF((G18=1),HLOOKUP(F18,B$65:F$66,2),HLOOKUP(F18,H$65:L$66,2))) -> 0 | M18: =IF(J18=0,0,J18-L$7+0.3*F18/1000+0.3) -> 0 | N18: =(IF(L18=0,0,IF(L18<1501,VLOOKUP(L18+M18,C$70:D$118,2),VLOOKUP(L18+M18,E$70:F$114,2))+(L$7-0.15)*I$5)*I$3*I$4*(100-F$5)/100) -> 0 | O18: =(((L18/1000)^2*PI()/4*F18/1000)-PI()/4*(F18/1000)^2*L18/1000+L18/1000)*F$4 -> 0 | P18: =IF(L18=0,0,I$6*I$3*I$4) -> 0 | Q18: =H18+N18+O18+P18 -> 0 | R18: =(L18=1200)*(15*L$4+L$4*M18)+(L18=1500)*(20*L$4+1.3*L$4*M18)+(L18=1800)*(30*L$4+1.5*L$4*M18)+(L18=2400)*(40*L$4+2*L$4*M18)+(L18=3000)*(50*L$4+2.5*L$4*M18)+(L18=3600)*(60*L$4+3*L$4*M18)+I18 -> 0 | S18: =F$3*(J18*(0.001*L18*1.3)^2*PI()/4) -> 0 | T18: =IF(L18=0,0,(Q18+R18+S18)/J18) -> 0 | U18: =Q18+R18+S18 -> 0 | V18: =U18*F$6 -> 0
A19: 9 | J19: =(C19-D19)*IF(F$7=1,1,0.3049) -> 0 | K19: =IF(E19=0,0,(D19-E19)*IF(F$7=1,1,0.3049)) -> 0 | L19: =IF(F19=0,0,IF((G19=1),HLOOKUP(F19,B$65:F$66,2),HLOOKUP(F19,H$65:L$66,2))) -> 0 | M19: =IF(J19=0,0,J19-L$7+0.3*F19/1000+0.3) -> 0 | N19: =(IF(L19=0,0,IF(L19<1501,VLOOKUP(L19+M19,C$70:D$118,2),VLOOKUP(L19+M19,E$70:F$114,2))+(L$7-0.15)*I$5)*I$3*I$4*(100-F$5)/100) -> 0 | O19: =(((L19/1000)^2*PI()/4*F19/1000)-PI()/4*(F19/1000)^2*L19/1000+L19/1000)*F$4 -> 0 | P19: =IF(L19=0,0,I$6*I$3*I$4) -> 0 | Q19: =H19+N19+O19+P19 -> 0 | R19: =(L19=1200)*(15*L$4+L$4*M19)+(L19=1500)*(20*L$4+1.3*L$4*M19)+(L19=1800)*(30*L$4+1.5*L$4*M19)+(L19=2400)*(40*L$4+2*L$4*M19)+(L19=3000)*(50*L$4+2.5*L$4*M19)+(L19=3600)*(60*L$4+3*L$4*M19)+I19 -> 0 | S19: =F$3*(J19*(0.001*L19*1.3)^2*PI()/4) -> 0 | T19: =IF(L19=0,0,(Q19+R19+S19)/J19) -> 0 | U19: =Q19+R19+S19 -> 0 | V19: =U19*F$6 -> 0
A20: 10 | J20: =(C20-D20)*IF(F$7=1,1,0.3049) -> 0 | K20: =IF(E20=0,0,(D20-E20)*IF(F$7=1,1,0.3049)) -> 0 | L20: =IF(F20=0,0,IF((G20=1),HLOOKUP(F20,B$65:F$66,2),HLOOKUP(F20,H$65:L$66,2))) -> 0 | M20: =IF(J20=0,0,J20-L$7+0.3*F20/1000+0.3) -> 0 | N20: =(IF(L20=0,0,IF(L20<1501,VLOOKUP(L20+M20,C$70:D$118,2),VLOOKUP(L20+M20,E$70:F$114,2))+(L$7-0.15)*I$5)*I$3*I$4*(100-F$5)/100) -> 0 | O20: =(((L20/1000)^2*PI()/4*F20/1000)-PI()/4*(F20/1000)^2*L20/1000+L20/1000)*F$4 -> 0 | P20: =IF(L20=0,0,I$6*I$3*I$4) -> 0 | Q20: =H20+N20+O20+P20 -> 0 | R20: =(L20=1200)*(15*L$4+L$4*M20)+(L20=1500)*(20*L$4+1.3*L$4*M20)+(L20=1800)*(30*L$4+1.5*L$4*M20)+(L20=2400)*(40*L$4+2*L$4*M20)+(L20=3000)*(50*L$4+2.5*L$4*M20)+(L20=3600)*(60*L$4+3*L$4*M20)+I20 -> 0 | S20: =F$3*(J20*(0.001*L20*1.3)^2*PI()/4) -> 0 | T20: =IF(L20=0,0,(Q20+R20+S20)/J20) -> 0 | U20: =Q20+R20+S20 -> 0 | V20: =U20*F$6 -> 0
A21: 11 | J21: =(C21-D21)*IF(F$7=1,1,0.3049) -> 0 | K21: =IF(E21=0,0,(D21-E21)*IF(F$7=1,1,0.3049)) -> 0 | L21: =IF(F21=0,0,IF((G21=1),HLOOKUP(F21,B$65:F$66,2),HLOOKUP(F21,H$65:L$66,2))) -> 0 | M21: =IF(J21=0,0,J21-L$7+0.3*F21/1000+0.3) -> 0 | N21: =(IF(L21=0,0,IF(L21<1501,VLOOKUP(L21+M21,C$70:D$118,2),VLOOKUP(L21+M21,E$70:F$114,2))+(L$7-0.15)*I$5)*I$3*I$4*(100-F$5)/100) -> 0 | O21: =(((L21/1000)^2*PI()/4*F21/1000)-PI()/4*(F21/1000)^2*L21/1000+L21/1000)*F$4 -> 0 | P21: =IF(L21=0,0,I$6*I$3*I$4) -> 0 | Q21: =H21+N21+O21+P21 -> 0 | R21: =(L21=1200)*(15*L$4+L$4*M21)+(L21=1500)*(20*L$4+1.3*L$4*M21)+(L21=1800)*(30*L$4+1.5*L$4*M21)+(L21=2400)*(40*L$4+2*L$4*M21)+(L21=3000)*(50*L$4+2.5*L$4*M21)+(L21=3600)*(60*L$4+3*L$4*M21)+I21 -> 0 | S21: =F$3*(J21*(0.001*L21*1.3)^2*PI()/4) -> 0 | T21: =IF(L21=0,0,(Q21+R21+S21)/J21) -> 0 | U21: =Q21+R21+S21 -> 0 | V21: =U21*F$6 -> 0
A22: 12 | J22: =(C22-D22)*IF(F$7=1,1,0.3049) -> 0 | K22: =IF(E22=0,0,(D22-E22)*IF(F$7=1,1,0.3049)) -> 0 | L22: =IF(F22=0,0,IF((G22=1),HLOOKUP(F22,B$65:F$66,2),HLOOKUP(F22,H$65:L$66,2))) -> 0 | M22: =IF(J22=0,0,J22-L$7+0.3*F22/1000+0.3) -> 0 | N22: =(IF(L22=0,0,IF(L22<1501,VLOOKUP(L22+M22,C$70:D$118,2),VLOOKUP(L22+M22,E$70:F$114,2))+(L$7-0.15)*I$5)*I$3*I$4*(100-F$5)/100) -> 0 | O22: =(((L22/1000)^2*PI()/4*F22/1000)-PI()/4*(F22/1000)^2*L22/1000+L22/1000)*F$4 -> 0 | P22: =IF(L22=0,0,I$6*I$3*I$4) -> 0 | Q22: =H22+N22+O22+P22 -> 0 | R22: =(L22=1200)*(15*L$4+L$4*M22)+(L22=1500)*(20*L$4+1.3*L$4*M22)+(L22=1800)*(30*L$4+1.5*L$4*M22)+(L22=2400)*(40*L$4+2*L$4*M22)+(L22=3000)*(50*L$4+2.5*L$4*M22)+(L22=3600)*(60*L$4+3*L$4*M22)+I22 -> 0 | S22: =F$3*(J22*(0.001*L22*1.3)^2*PI()/4) -> 0 | T22: =IF(L22=0,0,(Q22+R22+S22)/J22) -> 0 | U22: =Q22+R22+S22 -> 0 | V22: =U22*F$6 -> 0
... A46: 36 | J46: =(C46-D46)*IF(F$7=1,1,0.3049) -> 0 | K46: =IF(E46=0,0,(D46-E46)*IF(F$7=1,1,0.3049)) -> 0 | L46: =IF(F46=0,0,IF((G46=1),HLOOKUP(F46,B$65:F$66,2),HLOOKUP(F46,H$65:L$66,2))) -> 0 | M46: =IF(J46=0,0,J46-L$7+0.3*F46/1000+0.3) -> 0 | N46: =(IF(L46=0,0,IF(L46<1501,VLOOKUP(L46+M46,C$70:D$118,2),VLOOKUP(L46+M46,E$70:F$114,2))+(L$7-0.15)*I$5)*I$3*I$4*(100-F$5)/100) -> 0 | O46: =(((L46/1000)^2*PI()/4*F46/1000)-PI()/4*(F46/1000)^2*L46/1000+L46/1000)*F$4 -> 0 | P46: =IF(L46=0,0,I$6*I$3*I$4) -> 0 | Q46: =H46+N46+O46+P46 -> 0 | R46: =(L46=1200)*(15*L$4+L$4*M46)+(L46=1500)*(20*L$4+1.3*L$4*M46)+(L46=1800)*(30*L$4+1.5*L$4*M46)+(L46=2400)*(40*L$4+2*L$4*M46)+(L46=3000)*(50*L$4+2.5*L$4*M46)+(L46=3600)*(60*L$4+3*L$4*M46)+I46 -> 0 | S46: =F$3*(J46*(0.001*L46*1.3)^2*PI()/4) -> 0 | T46: =IF(L46=0,0,(Q46+R46+S46)/J46) -> 0 | U46: =Q46+R46+S46 -> 0 | V46: =U46*F$6 -> 0
A48: MANHOLE TOTALS | H48: =SUM(H9:H46) -> 0 | I48: =SUM(I9:I46) -> 0 | N48: =SUM(N11:N46) -> 0 | O48: =SUM(O11:O46) -> 0 | P48: =SUM(P11:P46) -> 0 | Q48: =SUM(Q11:Q46) -> 0 | R48: =SUM(R11:R46) -> 0 | S48: =SUM(S11:S46) -> 0 | U48: =SUM(U11:U46) -> 0 | V48: =SUM(V11:V46) -> 0
B51: CATCHBASINS
B52: ITEMS | C52: QNTY | D52: WALL" | E52: DPTHm | F52: $GT ea | G52: $/ADDMAT | H52: $/AD L&E | I52: $PRECST | J52: $CONC | K52: $FR&CV | L52: $MATRL | M52: $LAB&EQ | N52: $TRKNG | O52: $ EACH | P52: TOTAL $ | Q52: $ SALE/ | S52: TOTALS | T52: $COST | U52: $MARGIN | V52: $SALE
A53: 1 | B53: SINGLE C.B.'S | D53: 4 | E53: 2.2 | F53: 0 | G53: 0 | H53: 0 | I53: =(IF(D53=4,F$115,F$116)*L6*(E53-L7)+F53*I3*I$4+(L$7-0.15)*I$5)*C53 -> 0 | J53: =C53*0.5*F$4 -> 0 | K53: =C53*I$7*I$3*I$4 -> 0 | L53: =G53*C53+I53+J53+K53 -> 0 | M53: =C53*(C$59+H53) -> 0 | N53: =C53*E53*1*F$3 -> 0 | O53: =IF(C53=0,0,(L53+M53+N53)/C53) -> 0 | P53: =L53+M53+N53 -> 0 | Q53: =O53*F$6 -> 0
A54: 2 | B54: DOUBLE C.B.'S | D54: 4 | E54: 2.2 | F54: 0 | G54: 0 | H54: 0 | I54: =(F119*L6*(E54-L7)+F54*I3*I4+(L7-0.15)*I5*2)*C54 -> 0 | J54: =C54*1*F$4 -> 0 | K54: =C54*I$7*2*I$3*I$4 -> 0 | L54: =G54*C54+I54+J54+K54 -> 0 | M54: =C54*(C$60+H54) -> 0 | N54: =C54*E54*1.8*F$3 -> 0 | O54: =IF(C54=0,0,(L54+M54+N54)/C54) -> 0 | P54: =L54+M54+N54 -> 0 | Q54: =O54*F$6 -> 0 | S54: MATRLS | T54: =Q48+L57 -> 0 | U54: =(F6-1)*T54 -> 0 | V54: =T54+U54 -> 0
A55: 3 | B55: DITCH INLT CB'S | D55: 4 | E55: 2.2 | F55: 0 | G55: 0 | H55: 0 | I55: =(F117*L$6*(E55-L$7)+F55*I$3*I$4+(L7-0.15)*I$5)*C55 -> 0 | J55: =C55*0.5*F$4 -> 0 | K55: =C55*(F59*L6) -> 0 | L55: =G55*C55+I55+J55+K55 -> 0 | M55: =C55*(C$61+H55) -> 0 | N55: =C55*E55*1*F$3 -> 0 | O55: =IF(C55=0,0,(L55+M55+N55)/C55) -> 0 | P55: =L55+M55+N55 -> 0 | Q55: =O55*F$6 -> 0 | S55: L&E | T55: =R48+M57 -> 0 | U55: =(F6-1)*T55 -> 0 | V55: =T55+U55 -> 0
A56: 4 | B56: DDITCH INLT CB'S | D56: 4 | E56: 2.2 | F56: 0 | G56: 0 | H56: 0 | I56: =(F118*L$6*(E56-L$7)+F56*I$3*I$4+(L7-0.15)*I$5)*C56 -> 0 | J56: =C56*1*F$4 -> 0 | K56: =C56*(F60*L6) -> 0 | L56: =G56*C56+I56+J56+K56 -> 0 | M56: =C56*(C$62+H56) -> 0 | N56: =C56*E56*1.8*F$3 -> 0 | O56: =IF(C56=0,0,(L56+M56+N56)/C56) -> 0 | P56: =L56+M56+N56 -> 0 | Q56: =O56*F$6 -> 0 | S56: TRUCKING | T56: =S48+N57 -> 0 | U56: =(F6-1)*T56 -> 0 | V56: =T56+U56 -> 0
A57: CATCHBASIN TOTALS | C57: =SUM(C53:C56) -> 0 | G57: =SUM(G53:G56) -> 0 | H57: =SUM(H53:H56) -> 0 | I57: =SUM(I53:I56) -> 0 | J57: =SUM(J53:J56) -> 0 | K57: =SUM(K53:K56) -> 0 | L57: =SUM(L53:L56) -> 0 | M57: =SUM(M53:M56) -> 0 | N57: =SUM(N53:N56) -> 0 | P57: =SUM(P53:P56) -> 0 | Q57: =SUM(Q53:Q56) -> 0 | S57: BID PRICE | T57: =SUM(T54:T56) -> 0 | U57: =(F6-1)*T57 -> 0 | V57: =T57+U57 -> 0
B59: LABOR SCB | C59: 200 | E59: DICB F&C $ | F59: 465
B60: LABOR DCB | C60: 250 | E60: DDICB F&C $ | F60: 715
B61: LABOR DICB | C61: 220
B62: LABOR DDICB | C62: 280
A64: LOOKUP TABLE FOR MANHOLE SIZE
A65: PipeIDstr | B65: 50 | C65: 601 | D65: 826 | E65: 1051 | F65: 1501 | G65: PipeIDang | H65: 50 | I65: 451 | J65: 601 | K65: 826 | L65: 1051
A66: MH dia | B66: 1200 | C66: 1500 | D66: 1800 | E66: 2400 | F66: =NA() -> #N/A | G66: MHdia mm | H66: 1200 | I66: 1500 | J66: 1800 | K66: 2400 | L66: =NA() -> #N/A
A69: LOOKUP TABLE | C69: MH Prices June 2022 | G69: NOTE: Paste copy in boxed area of MH Pricer
C70: 1200 | D70: #N/A | E70: 1800 | F70: #N/A | G70: to this boxed area. USING "PASTE SPECIAL"
C71: 1201 | D71: 2254.681 | E71: 1801.67 | F71: 6780.1253 | G71: AND OPTING FOR TEXT ONLY.
C72: 1201.33 | D72: 2603.3108 | E72: 1802 | F72: 7531.5512
...

Sheet MANHOLES (2)
A1: TOPSITE CONTRACTING LIMITED - MANHOLE & CATCHBASIN ESTIMATE 2022
A3: JOB: | D3: $/CM TRUCKING | F3: 10 | H3: FSTfctr | I3: 1
D4: $/CM CONCRETE | F4: 250 | H4: PSTfct | I4: 1 | K4: LABOR/HR | L4: 110 | O4: =IF(F7=1,"METRIC","IMPERIAL") -> METRIC | P4: =O4 -> METRIC | Q4: =O4 -> METRIC
A5: DATE: | D5: %DISCOUNT | F5: 40 | H5: Mod$/m | I5: 718
D6: MARGIN FACTOR | F6: 1.1 | H6: MH F&C $ | I6: 375 | K6: DSC/TX FCTR | L6: 1 | U6: REVISED: | V6: 44859
C7: =O4 -> METRIC | D7: METRIC 1/ IMPER 0 | F7: 1 | H7: CB F&C $ | I7: 500 | K7: FR+CVR m | L7: 0.3 | U7: PRINTED: | V7: =TODAY() -> 46143
A9: Item | B9: MH Description | C9: Top El. | D9: Low Inv | E9: Hi Inv | F9: Pipe Out | G9: ST1/L2 | H9: Add$Mtrls | I9: Add$L&E | J9: Depth m | K9: Drop m | L9: MHdia-mm | M9: PCovrall | N9: $Precast | O9: $Conc | P9: $Fr&Cov | Q9: $Matrl | R9: $L&E | S9: $Trkng | T9: $/VM | U9: TOTAL $ | V9: SALE$
A10: 0
A11: 1 | J11: =(C11-D11)*IF(F$7=1,1,0.3049) -> 0 | K11: =IF(E11=0,0,(D11-E11)*IF(F$7=1,1,0.3049)) -> 0 | L11: =IF(F11=0,0,IF((G11=1),HLOOKUP(F11,B$65:F$66,2),HLOOKUP(F11,H$65:L$66,2))) -> 0 | M11: =IF(J11=0,0,J11-L$7+0.3*F11/1000+0.3) -> 0 | N11: =(IF(L11=0,0,IF(L11<1501,VLOOKUP(L11+M11,C$70:D$118,2),VLOOKUP(L11+M11,E$70:F$114,2))+(L$7-0.15)*I$5)*I$3*I$4*(100-F$5)/100) -> 0 | O11: =(((L11/1000)^2*PI()/4*F11/1000)-PI()/4*(F11/1000)^2*L11/1000+L11/1000)*F$4 -> 0 | P11: =IF(L11=0,0,I$6*I$3*I$4) -> 0 | Q11: =H11+N11+O11+P11 -> 0 | R11: =(L11=1200)*(15*L$4+L$4*M11)+(L11=1500)*(20*L$4+1.3*L$4*M11)+(L11=1800)*(30*L$4+1.5*L$4*M11)+(L11=2400)*(40*L$4+2*L$4*M11)+(L11=3000)*(50*L$4+2.5*L$4*M11)+(L11=3600)*(60*L$4+3*L$4*M11)+I11 -> 0 | S11: =F$3*(J11*(0.001*L11*1.3)^2*PI()/4) -> 0 | T11: =IF(L11=0,0,(Q11+R11+S11)/J11) -> 0 | U11: =Q11+R11+S11 -> 0 | V11: =U11*F$6 -> 0
A12: 2 | J12: =(C12-D12)*IF(F$7=1,1,0.3049) -> 0 | K12: =IF(E12=0,0,(D12-E12)*IF(F$7=1,1,0.3049)) -> 0 | L12: =IF(F12=0,0,IF((G12=1),HLOOKUP(F12,B$65:F$66,2),HLOOKUP(F12,H$65:L$66,2))) -> 0 | M12: =IF(J12=0,0,J12-L$7+0.3*F12/1000+0.3) -> 0 | N12: =(IF(L12=0,0,IF(L12<1501,VLOOKUP(L12+M12,C$70:D$118,2),VLOOKUP(L12+M12,E$70:F$114,2))+(L$7-0.15)*I$5)*I$3*I$4*(100-F$5)/100) -> 0 | O12: =(((L12/1000)^2*PI()/4*F12/1000)-PI()/4*(F12/1000)^2*L12/1000+L12/1000)*F$4 -> 0 | P12: =IF(L12=0,0,I$6*I$3*I$4) -> 0 | Q12: =H12+N12+O12+P12 -> 0 | R12: =(L12=1200)*(15*L$4+L$4*M12)+(L12=1500)*(20*L$4+1.3*L$4*M12)+(L12=1800)*(30*L$4+1.5*L$4*M12)+(L12=2400)*(40*L$4+2*L$4*M12)+(L12=3000)*(50*L$4+2.5*L$4*M12)+(L12=3600)*(60*L$4+3*L$4*M12)+I12 -> 0 | S12: =F$3*(J12*(0.001*L12*1.3)^2*PI()/4) -> 0 | T12: =IF(L12=0,0,(Q12+R12+S12)/J12) -> 0 | U12: =Q12+R12+S12 -> 0 | V12: =U12*F$6 -> 0
A13: 3 | J13: =(C13-D13)*IF(F$7=1,1,0.3049) -> 0 | K13: =IF(E13=0,0,(D13-E13)*IF(F$7=1,1,0.3049)) -> 0 | L13: =IF(F13=0,0,IF((G13=1),HLOOKUP(F13,B$65:F$66,2),HLOOKUP(F13,H$65:L$66,2))) -> 0 | M13: =IF(J13=0,0,J13-L$7+0.3*F13/1000+0.3) -> 0 | N13: =(IF(L13=0,0,IF(L13<1501,VLOOKUP(L13+M13,C$70:D$118,2),VLOOKUP(L13+M13,E$70:F$114,2))+(L$7-0.15)*I$5)*I$3*I$4*(100-F$5)/100) -> 0 | O13: =(((L13/1000)^2*PI()/4*F13/1000)-PI()/4*(F13/1000)^2*L13/1000+L13/1000)*F$4 -> 0 | P13: =IF(L13=0,0,I$6*I$3*I$4) -> 0 | Q13: =H13+N13+O13+P13 -> 0 | R13: =(L13=1200)*(15*L$4+L$4*M13)+(L13=1500)*(20*L$4+1.3*L$4*M13)+(L13=1800)*(30*L$4+1.5*L$4*M13)+(L13=2400)*(40*L$4+2*L$4*M13)+(L13=3000)*(50*L$4+2.5*L$4*M13)+(L13=3600)*(60*L$4+3*L$4*M13)+I13 -> 0 | S13: =F$3*(J13*(0.001*L13*1.3)^2*PI()/4) -> 0 | T13: =IF(L13=0,0,(Q13+R13+S13)/J13) -> 0 | U13: =Q13+R13+S13 -> 0 | V13: =U13*F$6 -> 0
A14: 4 | J14: =(C14-D14)*IF(F$7=1,1,0.3049) -> 0 | K14: =IF(E14=0,0,(D14-E14)*IF(F$7=1,1,0.3049)) -> 0 | L14: =IF(F14=0,0,IF((G14=1),HLOOKUP(F14,B$65:F$66,2),HLOOKUP(F14,H$65:L$66,2))) -> 0 | M14: =IF(J14=0,0,J14-L$7+0.3*F14/1000+0.3) -> 0 | N14: =(IF(L14=0,0,IF(L14<1501,VLOOKUP(L14+M14,C$70:D$118,2),VLOOKUP(L14+M14,E$70:F$114,2))+(L$7-0.15)*I$5)*I$3*I$4*(100-F$5)/100) -> 0 | O14: =(((L14/1000)^2*PI()/4*F14/1000)-PI()/4*(F14/1000)^2*L14/1000+L14/1000)*F$4 -> 0 | P14: =IF(L14=0,0,I$6*I$3*I$4) -> 0 | Q14: =H14+N14+O14+P14 -> 0 | R14: =(L14=1200)*(15*L$4+L$4*M14)+(L14=1500)*(20*L$4+1.3*L$4*M14)+(L14=1800)*(30*L$4+1.5*L$4*M14)+(L14=2400)*(40*L$4+2*L$4*M14)+(L14=3000)*(50*L$4+2.5*L$4*M14)+(L14=3600)*(60*L$4+3*L$4*M14)+I14 -> 0 | S14: =F$3*(J14*(0.001*L14*1.3)^2*PI()/4) -> 0 | T14: =IF(L14=0,0,(Q14+R14+S14)/J14) -> 0 | U14: =Q14+R14+S14 -> 0 | V14: =U14*F$6 -> 0
A15: 5 | J15: =(C15-D15)*IF(F$7=1,1,0.3049) -> 0 | K15: =IF(E15=0,0,(D15-E15)*IF(F$7=1,1,0.3049)) -> 0 | L15: =IF(F15=0,0,IF((G15=1),HLOOKUP(F15,B$65:F$66,2),HLOOKUP(F15,H$65:L$66,2))) -> 0 | M15: =IF(J15=0,0,J15-L$7+0.3*F15/1000+0.3) -> 0 | N15: =(IF(L15=0,0,IF(L15<1501,VLOOKUP(L15+M15,C$70:D$118,2),VLOOKUP(L15+M15,E$70:F$114,2))+(L$7-0.15)*I$5)*I$3*I$4*(100-F$5)/100) -> 0 | O15: =(((L15/1000)^2*PI()/4*F15/1000)-PI()/4*(F15/1000)^2*L15/1000+L15/1000)*F$4 -> 0 | P15: =IF(L15=0,0,I$6*I$3*I$4) -> 0 | Q15: =H15+N15+O15+P15 -> 0 | R15: =(L15=1200)*(15*L$4+L$4*M15)+(L15=1500)*(20*L$4+1.3*L$4*M15)+(L15=1800)*(30*L$4+1.5*L$4*M15)+(L15=2400)*(40*L$4+2*L$4*M15)+(L15=3000)*(50*L$4+2.5*L$4*M15)+(L15=3600)*(60*L$4+3*L$4*M15)+I15 -> 0 | S15: =F$3*(J15*(0.001*L15*1.3)^2*PI()/4) -> 0 | T15: =IF(L15=0,0,(Q15+R15+S15)/J15) -> 0 | U15: =Q15+R15+S15 -> 0 | V15: =U15*F$6 -> 0
A16: 6 | J16: =(C16-D16)*IF(F$7=1,1,0.3049) -> 0 | K16: =IF(E16=0,0,(D16-E16)*IF(F$7=1,1,0.3049)) -> 0 | L16: =IF(F16=0,0,IF((G16=1),HLOOKUP(F16,B$65:F$66,2),HLOOKUP(F16,H$65:L$66,2))) -> 0 | M16: =IF(J16=0,0,J16-L$7+0.3*F16/1000+0.3) -> 0 | N16: =(IF(L16=0,0,IF(L16<1501,VLOOKUP(L16+M16,C$70:D$118,2),VLOOKUP(L16+M16,E$70:F$114,2))+(L$7-0.15)*I$5)*I$3*I$4*(100-F$5)/100) -> 0 | O16: =(((L16/1000)^2*PI()/4*F16/1000)-PI()/4*(F16/1000)^2*L16/1000+L16/1000)*F$4 -> 0 | P16: =IF(L16=0,0,I$6*I$3*I$4) -> 0 | Q16: =H16+N16+O16+P16 -> 0 | R16: =(L16=1200)*(15*L$4+L$4*M16)+(L16=1500)*(20*L$4+1.3*L$4*M16)+(L16=1800)*(30*L$4+1.5*L$4*M16)+(L16=2400)*(40*L$4+2*L$4*M16)+(L16=3000)*(50*L$4+2.5*L$4*M16)+(L16=3600)*(60*L$4+3*L$4*M16)+I16 -> 0 | S16: =F$3*(J16*(0.001*L16*1.3)^2*PI()/4) -> 0 | T16: =IF(L16=0,0,(Q16+R16+S16)/J16) -> 0 | U16: =Q16+R16+S16 -> 0 | V16: =U16*F$6 -> 0
A17: 7 | J17: =(C17-D17)*IF(F$7=1,1,0.3049) -> 0 | K17: =IF(E17=0,0,(D17-E17)*IF(F$7=1,1,0.3049)) -> 0 | L17: =IF(F17=0,0,IF((G17=1),HLOOKUP(F17,B$65:F$66,2),HLOOKUP(F17,H$65:L$66,2))) -> 0 | M17: =IF(J17=0,0,J17-L$7+0.3*F17/1000+0.3) -> 0 | N17: =(IF(L17=0,0,IF(L17<1501,VLOOKUP(L17+M17,C$70:D$118,2),VLOOKUP(L17+M17,E$70:F$114,2))+(L$7-0.15)*I$5)*I$3*I$4*(100-F$5)/100) -> 0 | O17: =(((L17/1000)^2*PI()/4*F17/1000)-PI()/4*(F17/1000)^2*L17/1000+L17/1000)*F$4 -> 0 | P17: =IF(L17=0,0,I$6*I$3*I$4) -> 0 | Q17: =H17+N17+O17+P17 -> 0 | R17: =(L17=1200)*(15*L$4+L$4*M17)+(L17=1500)*(20*L$4+1.3*L$4*M17)+(L17=1800)*(30*L$4+1.5*L$4*M17)+(L17=2400)*(40*L$4+2*L$4*M17)+(L17=3000)*(50*L$4+2.5*L$4*M17)+(L17=3600)*(60*L$4+3*L$4*M17)+I17 -> 0 | S17: =F$3*(J17*(0.001*L17*1.3)^2*PI()/4) -> 0 | T17: =IF(L17=0,0,(Q17+R17+S17)/J17) -> 0 | U17: =Q17+R17+S17 -> 0 | V17: =U17*F$6 -> 0
A18: 8 | J18: =(C18-D18)*IF(F$7=1,1,0.3049) -> 0 | K18: =IF(E18=0,0,(D18-E18)*IF(F$7=1,1,0.3049)) -> 0 | L18: =IF(F18=0,0,IF((G18=1),HLOOKUP(F18,B$65:F$66,2),HLOOKUP(F18,H$65:L$66,2))) -> 0 | M18: =IF(J18=0,0,J18-L$7+0.3*F18/1000+0.3) -> 0 | N18: =(IF(L18=0,0,IF(L18<1501,VLOOKUP(L18+M18,C$70:D$118,2),VLOOKUP(L18+M18,E$70:F$114,2))+(L$7-0.15)*I$5)*I$3*I$4*(100-F$5)/100) -> 0 | O18: =(((L18/1000)^2*PI()/4*F18/1000)-PI()/4*(F18/1000)^2*L18/1000+L18/1000)*F$4 -> 0 | P18: =IF(L18=0,0,I$6*I$3*I$4) -> 0 | Q18: =H18+N18+O18+P18 -> 0 | R18: =(L18=1200)*(15*L$4+L$4*M18)+(L18=1500)*(20*L$4+1.3*L$4*M18)+(L18=1800)*(30*L$4+1.5*L$4*M18)+(L18=2400)*(40*L$4+2*L$4*M18)+(L18=3000)*(50*L$4+2.5*L$4*M18)+(L18=3600)*(60*L$4+3*L$4*M18)+I18 -> 0 | S18: =F$3*(J18*(0.001*L18*1.3)^2*PI()/4) -> 0 | T18: =IF(L18=0,0,(Q18+R18+S18)/J18) -> 0 | U18: =Q18+R18+S18 -> 0 | V18: =U18*F$6 -> 0
A19: 9 | J19: =(C19-D19)*IF(F$7=1,1,0.3049) -> 0 | K19: =IF(E19=0,0,(D19-E19)*IF(F$7=1,1,0.3049)) -> 0 | L19: =IF(F19=0,0,IF((G19=1),HLOOKUP(F19,B$65:F$66,2),HLOOKUP(F19,H$65:L$66,2))) -> 0 | M19: =IF(J19=0,0,J19-L$7+0.3*F19/1000+0.3) -> 0 | N19: =(IF(L19=0,0,IF(L19<1501,VLOOKUP(L19+M19,C$70:D$118,2),VLOOKUP(L19+M19,E$70:F$114,2))+(L$7-0.15)*I$5)*I$3*I$4*(100-F$5)/100) -> 0 | O19: =(((L19/1000)^2*PI()/4*F19/1000)-PI()/4*(F19/1000)^2*L19/1000+L19/1000)*F$4 -> 0 | P19: =IF(L19=0,0,I$6*I$3*I$4) -> 0 | Q19: =H19+N19+O19+P19 -> 0 | R19: =(L19=1200)*(15*L$4+L$4*M19)+(L19=1500)*(20*L$4+1.3*L$4*M19)+(L19=1800)*(30*L$4+1.5*L$4*M19)+(L19=2400)*(40*L$4+2*L$4*M19)+(L19=3000)*(50*L$4+2.5*L$4*M19)+(L19=3600)*(60*L$4+3*L$4*M19)+I19 -> 0 | S19: =F$3*(J19*(0.001*L19*1.3)^2*PI()/4) -> 0 | T19: =IF(L19=0,0,(Q19+R19+S19)/J19) -> 0 | U19: =Q19+R19+S19 -> 0 | V19: =U19*F$6 -> 0
A20: 10 | J20: =(C20-D20)*IF(F$7=1,1,0.3049) -> 0 | K20: =IF(E20=0,0,(D20-E20)*IF(F$7=1,1,0.3049)) -> 0 | L20: =IF(F20=0,0,IF((G20=1),HLOOKUP(F20,B$65:F$66,2),HLOOKUP(F20,H$65:L$66,2))) -> 0 | M20: =IF(J20=0,0,J20-L$7+0.3*F20/1000+0.3) -> 0 | N20: =(IF(L20=0,0,IF(L20<1501,VLOOKUP(L20+M20,C$70:D$118,2),VLOOKUP(L20+M20,E$70:F$114,2))+(L$7-0.15)*I$5)*I$3*I$4*(100-F$5)/100) -> 0 | O20: =(((L20/1000)^2*PI()/4*F20/1000)-PI()/4*(F20/1000)^2*L20/1000+L20/1000)*F$4 -> 0 | P20: =IF(L20=0,0,I$6*I$3*I$4) -> 0 | Q20: =H20+N20+O20+P20 -> 0 | R20: =(L20=1200)*(15*L$4+L$4*M20)+(L20=1500)*(20*L$4+1.3*L$4*M20)+(L20=1800)*(30*L$4+1.5*L$4*M20)+(L20=2400)*(40*L$4+2*L$4*M20)+(L20=3000)*(50*L$4+2.5*L$4*M20)+(L20=3600)*(60*L$4+3*L$4*M20)+I20 -> 0 | S20: =F$3*(J20*(0.001*L20*1.3)^2*PI()/4) -> 0 | T20: =IF(L20=0,0,(Q20+R20+S20)/J20) -> 0 | U20: =Q20+R20+S20 -> 0 | V20: =U20*F$6 -> 0
A21: 11 | J21: =(C21-D21)*IF(F$7=1,1,0.3049) -> 0 | K21: =IF(E21=0,0,(D21-E21)*IF(F$7=1,1,0.3049)) -> 0 | L21: =IF(F21=0,0,IF((G21=1),HLOOKUP(F21,B$65:F$66,2),HLOOKUP(F21,H$65:L$66,2))) -> 0 | M21: =IF(J21=0,0,J21-L$7+0.3*F21/1000+0.3) -> 0 | N21: =(IF(L21=0,0,IF(L21<1501,VLOOKUP(L21+M21,C$70:D$118,2),VLOOKUP(L21+M21,E$70:F$114,2))+(L$7-0.15)*I$5)*I$3*I$4*(100-F$5)/100) -> 0 | O21: =(((L21/1000)^2*PI()/4*F21/1000)-PI()/4*(F21/1000)^2*L21/1000+L21/1000)*F$4 -> 0 | P21: =IF(L21=0,0,I$6*I$3*I$4) -> 0 | Q21: =H21+N21+O21+P21 -> 0 | R21: =(L21=1200)*(15*L$4+L$4*M21)+(L21=1500)*(20*L$4+1.3*L$4*M21)+(L21=1800)*(30*L$4+1.5*L$4*M21)+(L21=2400)*(40*L$4+2*L$4*M21)+(L21=3000)*(50*L$4+2.5*L$4*M21)+(L21=3600)*(60*L$4+3*L$4*M21)+I21 -> 0 | S21: =F$3*(J21*(0.001*L21*1.3)^2*PI()/4) -> 0 | T21: =IF(L21=0,0,(Q21+R21+S21)/J21) -> 0 | U21: =Q21+R21+S21 -> 0 | V21: =U21*F$6 -> 0
A22: 12 | J22: =(C22-D22)*IF(F$7=1,1,0.3049) -> 0 | K22: =IF(E22=0,0,(D22-E22)*IF(F$7=1,1,0.3049)) -> 0 | L22: =IF(F22=0,0,IF((G22=1),HLOOKUP(F22,B$65:F$66,2),HLOOKUP(F22,H$65:L$66,2))) -> 0 | M22: =IF(J22=0,0,J22-L$7+0.3*F22/1000+0.3) -> 0 | N22: =(IF(L22=0,0,IF(L22<1501,VLOOKUP(L22+M22,C$70:D$118,2),VLOOKUP(L22+M22,E$70:F$114,2))+(L$7-0.15)*I$5)*I$3*I$4*(100-F$5)/100) -> 0 | O22: =(((L22/1000)^2*PI()/4*F22/1000)-PI()/4*(F22/1000)^2*L22/1000+L22/1000)*F$4 -> 0 | P22: =IF(L22=0,0,I$6*I$3*I$4) -> 0 | Q22: =H22+N22+O22+P22 -> 0 | R22: =(L22=1200)*(15*L$4+L$4*M22)+(L22=1500)*(20*L$4+1.3*L$4*M22)+(L22=1800)*(30*L$4+1.5*L$4*M22)+(L22=2400)*(40*L$4+2*L$4*M22)+(L22=3000)*(50*L$4+2.5*L$4*M22)+(L22=3600)*(60*L$4+3*L$4*M22)+I22 -> 0 | S22: =F$3*(J22*(0.001*L22*1.3)^2*PI()/4) -> 0 | T22: =IF(L22=0,0,(Q22+R22+S22)/J22) -> 0 | U22: =Q22+R22+S22 -> 0 | V22: =U22*F$6 -> 0
... A46: 36 | J46: =(C46-D46)*IF(F$7=1,1,0.3049) -> 0 | K46: =IF(E46=0,0,(D46-E46)*IF(F$7=1,1,0.3049)) -> 0 | L46: =IF(F46=0,0,IF((G46=1),HLOOKUP(F46,B$65:F$66,2),HLOOKUP(F46,H$65:L$66,2))) -> 0 | M46: =IF(J46=0,0,J46-L$7+0.3*F46/1000+0.3) -> 0 | N46: =(IF(L46=0,0,IF(L46<1501,VLOOKUP(L46+M46,C$70:D$118,2),VLOOKUP(L46+M46,E$70:F$114,2))+(L$7-0.15)*I$5)*I$3*I$4*(100-F$5)/100) -> 0 | O46: =(((L46/1000)^2*PI()/4*F46/1000)-PI()/4*(F46/1000)^2*L46/1000+L46/1000)*F$4 -> 0 | P46: =IF(L46=0,0,I$6*I$3*I$4) -> 0 | Q46: =H46+N46+O46+P46 -> 0 | R46: =(L46=1200)*(15*L$4+L$4*M46)+(L46=1500)*(20*L$4+1.3*L$4*M46)+(L46=1800)*(30*L$4+1.5*L$4*M46)+(L46=2400)*(40*L$4+2*L$4*M46)+(L46=3000)*(50*L$4+2.5*L$4*M46)+(L46=3600)*(60*L$4+3*L$4*M46)+I46 -> 0 | S46: =F$3*(J46*(0.001*L46*1.3)^2*PI()/4) -> 0 | T46: =IF(L46=0,0,(Q46+R46+S46)/J46) -> 0 | U46: =Q46+R46+S46 -> 0 | V46: =U46*F$6 -> 0
A48: MANHOLE TOTALS | H48: =SUM(H9:H46) -> 0 | I48: =SUM(I9:I46) -> 0 | N48: =SUM(N11:N46) -> 0 | O48: =SUM(O11:O46) -> 0 | P48: =SUM(P11:P46) -> 0 | Q48: =SUM(Q11:Q46) -> 0 | R48: =SUM(R11:R46) -> 0 | S48: =SUM(S11:S46) -> 0 | U48: =SUM(U11:U46) -> 0 | V48: =SUM(V11:V46) -> 0
B51: CATCHBASINS
B52: ITEMS | C52: QNTY | D52: WALL" | E52: DPTHm | F52: $GT ea | G52: $/ADDMAT | H52: $/AD L&E | I52: $PRECST | J52: $CONC | K52: $FR&CV | L52: $MATRL | M52: $LAB&EQ | N52: $TRKNG | O52: $ EACH | P52: TOTAL $ | Q52: $ SALE/ | S52: TOTALS | T52: $COST | U52: $MARGIN | V52: $SALE
A53: 1 | B53: SINGLE C.B.'S | D53: 4 | E53: 2.2 | F53: 0 | G53: 0 | H53: 0 | I53: =(IF(D53=4,F$115,F$116)*L6*(E53-L7)+F53*I3*I$4+(L$7-0.15)*I$5)*C53 -> 0 | J53: =C53*0.5*F$4 -> 0 | K53: =C53*I$7*I$3*I$4 -> 0 | L53: =G53*C53+I53+J53+K53 -> 0 | M53: =C53*(C$59+H53) -> 0 | N53: =C53*E53*1*F$3 -> 0 | O53: =IF(C53=0,0,(L53+M53+N53)/C53) -> 0 | P53: =L53+M53+N53 -> 0 | Q53: =O53*F$6 -> 0
A54: 2 | B54: DOUBLE C.B.'S | D54: 4 | E54: 2.2 | F54: 0 | G54: 0 | H54: 0 | I54: =(F119*L6*(E54-L7)+F54*I3*I4+(L7-0.15)*I5*2)*C54 -> 0 | J54: =C54*1*F$4 -> 0 | K54: =C54*I$7*2*I$3*I$4 -> 0 | L54: =G54*C54+I54+J54+K54 -> 0 | M54: =C54*(C$60+H54) -> 0 | N54: =C54*E54*1.8*F$3 -> 0 | O54: =IF(C54=0,0,(L54+M54+N54)/C54) -> 0 | P54: =L54+M54+N54 -> 0 | Q54: =O54*F$6 -> 0 | S54: MATRLS | T54: =Q48+L57 -> 0 | U54: =(F6-1)*T54 -> 0 | V54: =T54+U54 -> 0
A55: 3 | B55: DITCH INLT CB'S | D55: 4 | E55: 2.2 | F55: 0 | G55: 0 | H55: 0 | I55: =(F117*L$6*(E55-L$7)+F55*I$3*I$4+(L7-0.15)*I$5)*C55 -> 0 | J55: =C55*0.5*F$4 -> 0 | K55: =C55*(F59*L6) -> 0 | L55: =G55*C55+I55+J55+K55 -> 0 | M55: =C55*(C$61+H55) -> 0 | N55: =C55*E55*1*F$3 -> 0 | O55: =IF(C55=0,0,(L55+M55+N55)/C55) -> 0 | P55: =L55+M55+N55 -> 0 | Q55: =O55*F$6 -> 0 | S55: L&E | T55: =R48+M57 -> 0 | U55: =(F6-1)*T55 -> 0 | V55: =T55+U55 -> 0
A56: 4 | B56: DDITCH INLT CB'S | D56: 4 | E56: 2.2 | F56: 0 | G56: 0 | H56: 0 | I56: =(F118*L$6*(E56-L$7)+F56*I$3*I$4+(L7-0.15)*I$5)*C56 -> 0 | J56: =C56*1*F$4 -> 0 | K56: =C56*(F60*L6) -> 0 | L56: =G56*C56+I56+J56+K56 -> 0 | M56: =C56*(C$62+H56) -> 0 | N56: =C56*E56*1.8*F$3 -> 0 | O56: =IF(C56=0,0,(L56+M56+N56)/C56) -> 0 | P56: =L56+M56+N56 -> 0 | Q56: =O56*F$6 -> 0 | S56: TRUCKING | T56: =S48+N57 -> 0 | U56: =(F6-1)*T56 -> 0 | V56: =T56+U56 -> 0
A57: CATCHBASIN TOTALS | C57: =SUM(C53:C56) -> 0 | G57: =SUM(G53:G56) -> 0 | H57: =SUM(H53:H56) -> 0 | I57: =SUM(I53:I56) -> 0 | J57: =SUM(J53:J56) -> 0 | K57: =SUM(K53:K56) -> 0 | L57: =SUM(L53:L56) -> 0 | M57: =SUM(M53:M56) -> 0 | N57: =SUM(N53:N56) -> 0 | P57: =SUM(P53:P56) -> 0 | Q57: =SUM(Q53:Q56) -> 0 | S57: BID PRICE | T57: =SUM(T54:T56) -> 0 | U57: =(F6-1)*T57 -> 0 | V57: =T57+U57 -> 0
B59: LABOR SCB | C59: 200 | E59: DICB F&C $ | F59: 465
B60: LABOR DCB | C60: 250 | E60: DDICB F&C $ | F60: 715
B61: LABOR DICB | C61: 220
B62: LABOR DDICB | C62: 280
A64: LOOKUP TABLE FOR MANHOLE SIZE
A65: PipeIDstr | B65: 50 | C65: 601 | D65: 826 | E65: 1051 | F65: 1501 | G65: PipeIDang | H65: 50 | I65: 451 | J65: 601 | K65: 826 | L65: 1051
A66: MH dia | B66: 1200 | C66: 1500 | D66: 1800 | E66: 2400 | F66: =NA() -> #N/A | G66: MHdia mm | H66: 1200 | I66: 1500 | J66: 1800 | K66: 2400 | L66: =NA() -> #N/A
A69: LOOKUP TABLE | C69: MH Prices June 2022 | G69: NOTE: Paste copy in boxed area of MH Pricer
C70: 1200 | D70: #N/A | E70: 1800 | F70: #N/A | G70: to this boxed area. USING "PASTE SPECIAL"
C71: 1201 | D71: 2254.681 | E71: 1801.67 | F71: 6780.1253 | G71: AND OPTING FOR TEXT ONLY.
C72: 1201.33 | D72: 2603.3108 | E72: 1802 | F72: 7531.5512
...

Sheet MANHOLES (3)
A1: TOPSITE CONTRACTING LIMITED - MANHOLE & CATCHBASIN ESTIMATE 2022
A3: JOB: | D3: $/CM TRUCKING | F3: 10 | H3: FSTfctr | I3: 1
D4: $/CM CONCRETE | F4: 250 | H4: PSTfct | I4: 1 | K4: LABOR/HR | L4: 110 | O4: =IF(F7=1,"METRIC","IMPERIAL") -> METRIC | P4: =O4 -> METRIC | Q4: =O4 -> METRIC
A5: DATE: | B5: 44859 | D5: %DISCOUNT | F5: 40 | H5: Mod$/m | I5: 718
D6: MARGIN FACTOR | F6: 1.1 | H6: MH F&C $ | I6: 375 | K6: DSC/TX FCTR | L6: 1 | U6: REVISED: | V6: 44859
C7: =O4 -> METRIC | D7: METRIC 1/ IMPER 0 | F7: 1 | H7: CB F&C $ | I7: 500 | K7: FR+CVR m | L7: 0.3 | U7: PRINTED: | V7: =TODAY() -> 46143
A9: Item | B9: MH Description | C9: Top El. | D9: Low Inv | E9: Hi Inv | F9: Pipe Out | G9: ST1/L2 | H9: Add$Mtrls | I9: Add$L&E | J9: Depth m | K9: Drop m | L9: MHdia-mm | M9: PCovrall | N9: $Precast | O9: $Conc | P9: $Fr&Cov | Q9: $Matrl | R9: $L&E | S9: $Trkng | T9: $/VM | U9: TOTAL $ | V9: SALE$
A10: 0
A11: 1 | J11: =(C11-D11)*IF(F$7=1,1,0.3049) -> 0 | K11: =IF(E11=0,0,(D11-E11)*IF(F$7=1,1,0.3049)) -> 0 | L11: =IF(F11=0,0,IF((G11=1),HLOOKUP(F11,B$65:F$66,2),HLOOKUP(F11,H$65:L$66,2))) -> 0 | M11: =IF(J11=0,0,J11-L$7+0.3*F11/1000+0.3) -> 0 | N11: =(IF(L11=0,0,IF(L11<1501,VLOOKUP(L11+M11,C$70:D$118,2),VLOOKUP(L11+M11,E$70:F$114,2))+(L$7-0.15)*I$5)*I$3*I$4*(100-F$5)/100) -> 0 | O11: =(((L11/1000)^2*PI()/4*F11/1000)-PI()/4*(F11/1000)^2*L11/1000+L11/1000)*F$4 -> 0 | P11: =IF(L11=0,0,I$6*I$3*I$4) -> 0 | Q11: =H11+N11+O11+P11 -> 0 | R11: =(L11=1200)*(15*L$4+L$4*M11)+(L11=1500)*(20*L$4+1.3*L$4*M11)+(L11=1800)*(30*L$4+1.5*L$4*M11)+(L11=2400)*(40*L$4+2*L$4*M11)+(L11=3000)*(50*L$4+2.5*L$4*M11)+(L11=3600)*(60*L$4+3*L$4*M11)+I11 -> 0 | S11: =F$3*(J11*(0.001*L11*1.3)^2*PI()/4) -> 0 | T11: =IF(L11=0,0,(Q11+R11+S11)/J11) -> 0 | U11: =Q11+R11+S11 -> 0 | V11: =U11*F$6 -> 0
A12: 2 | J12: =(C12-D12)*IF(F$7=1,1,0.3049) -> 0 | K12: =IF(E12=0,0,(D12-E12)*IF(F$7=1,1,0.3049)) -> 0 | L12: =IF(F12=0,0,IF((G12=1),HLOOKUP(F12,B$65:F$66,2),HLOOKUP(F12,H$65:L$66,2))) -> 0 | M12: =IF(J12=0,0,J12-L$7+0.3*F12/1000+0.3) -> 0 | N12: =(IF(L12=0,0,IF(L12<1501,VLOOKUP(L12+M12,C$70:D$118,2),VLOOKUP(L12+M12,E$70:F$114,2))+(L$7-0.15)*I$5)*I$3*I$4*(100-F$5)/100) -> 0 | O12: =(((L12/1000)^2*PI()/4*F12/1000)-PI()/4*(F12/1000)^2*L12/1000+L12/1000)*F$4 -> 0 | P12: =IF(L12=0,0,I$6*I$3*I$4) -> 0 | Q12: =H12+N12+O12+P12 -> 0 | R12: =(L12=1200)*(15*L$4+L$4*M12)+(L12=1500)*(20*L$4+1.3*L$4*M12)+(L12=1800)*(30*L$4+1.5*L$4*M12)+(L12=2400)*(40*L$4+2*L$4*M12)+(L12=3000)*(50*L$4+2.5*L$4*M12)+(L12=3600)*(60*L$4+3*L$4*M12)+I12 -> 0 | S12: =F$3*(J12*(0.001*L12*1.3)^2*PI()/4) -> 0 | T12: =IF(L12=0,0,(Q12+R12+S12)/J12) -> 0 | U12: =Q12+R12+S12 -> 0 | V12: =U12*F$6 -> 0
A13: 3 | J13: =(C13-D13)*IF(F$7=1,1,0.3049) -> 0 | K13: =IF(E13=0,0,(D13-E13)*IF(F$7=1,1,0.3049)) -> 0 | L13: =IF(F13=0,0,IF((G13=1),HLOOKUP(F13,B$65:F$66,2),HLOOKUP(F13,H$65:L$66,2))) -> 0 | M13: =IF(J13=0,0,J13-L$7+0.3*F13/1000+0.3) -> 0 | N13: =(IF(L13=0,0,IF(L13<1501,VLOOKUP(L13+M13,C$70:D$118,2),VLOOKUP(L13+M13,E$70:F$114,2))+(L$7-0.15)*I$5)*I$3*I$4*(100-F$5)/100) -> 0 | O13: =(((L13/1000)^2*PI()/4*F13/1000)-PI()/4*(F13/1000)^2*L13/1000+L13/1000)*F$4 -> 0 | P13: =IF(L13=0,0,I$6*I$3*I$4) -> 0 | Q13: =H13+N13+O13+P13 -> 0 | R13: =(L13=1200)*(15*L$4+L$4*M13)+(L13=1500)*(20*L$4+1.3*L$4*M13)+(L13=1800)*(30*L$4+1.5*L$4*M13)+(L13=2400)*(40*L$4+2*L$4*M13)+(L13=3000)*(50*L$4+2.5*L$4*M13)+(L13=3600)*(60*L$4+3*L$4*M13)+I13 -> 0 | S13: =F$3*(J13*(0.001*L13*1.3)^2*PI()/4) -> 0 | T13: =IF(L13=0,0,(Q13+R13+S13)/J13) -> 0 | U13: =Q13+R13+S13 -> 0 | V13: =U13*F$6 -> 0
A14: 4 | J14: =(C14-D14)*IF(F$7=1,1,0.3049) -> 0 | K14: =IF(E14=0,0,(D14-E14)*IF(F$7=1,1,0.3049)) -> 0 | L14: =IF(F14=0,0,IF((G14=1),HLOOKUP(F14,B$65:F$66,2),HLOOKUP(F14,H$65:L$66,2))) -> 0 | M14: =IF(J14=0,0,J14-L$7+0.3*F14/1000+0.3) -> 0 | N14: =(IF(L14=0,0,IF(L14<1501,VLOOKUP(L14+M14,C$70:D$118,2),VLOOKUP(L14+M14,E$70:F$114,2))+(L$7-0.15)*I$5)*I$3*I$4*(100-F$5)/100) -> 0 | O14: =(((L14/1000)^2*PI()/4*F14/1000)-PI()/4*(F14/1000)^2*L14/1000+L14/1000)*F$4 -> 0 | P14: =IF(L14=0,0,I$6*I$3*I$4) -> 0 | Q14: =H14+N14+O14+P14 -> 0 | R14: =(L14=1200)*(15*L$4+L$4*M14)+(L14=1500)*(20*L$4+1.3*L$4*M14)+(L14=1800)*(30*L$4+1.5*L$4*M14)+(L14=2400)*(40*L$4+2*L$4*M14)+(L14=3000)*(50*L$4+2.5*L$4*M14)+(L14=3600)*(60*L$4+3*L$4*M14)+I14 -> 0 | S14: =F$3*(J14*(0.001*L14*1.3)^2*PI()/4) -> 0 | T14: =IF(L14=0,0,(Q14+R14+S14)/J14) -> 0 | U14: =Q14+R14+S14 -> 0 | V14: =U14*F$6 -> 0
A15: 5 | J15: =(C15-D15)*IF(F$7=1,1,0.3049) -> 0 | K15: =IF(E15=0,0,(D15-E15)*IF(F$7=1,1,0.3049)) -> 0 | L15: =IF(F15=0,0,IF((G15=1),HLOOKUP(F15,B$65:F$66,2),HLOOKUP(F15,H$65:L$66,2))) -> 0 | M15: =IF(J15=0,0,J15-L$7+0.3*F15/1000+0.3) -> 0 | N15: =(IF(L15=0,0,IF(L15<1501,VLOOKUP(L15+M15,C$70:D$118,2),VLOOKUP(L15+M15,E$70:F$114,2))+(L$7-0.15)*I$5)*I$3*I$4*(100-F$5)/100) -> 0 | O15: =(((L15/1000)^2*PI()/4*F15/1000)-PI()/4*(F15/1000)^2*L15/1000+L15/1000)*F$4 -> 0 | P15: =IF(L15=0,0,I$6*I$3*I$4) -> 0 | Q15: =H15+N15+O15+P15 -> 0 | R15: =(L15=1200)*(15*L$4+L$4*M15)+(L15=1500)*(20*L$4+1.3*L$4*M15)+(L15=1800)*(30*L$4+1.5*L$4*M15)+(L15=2400)*(40*L$4+2*L$4*M15)+(L15=3000)*(50*L$4+2.5*L$4*M15)+(L15=3600)*(60*L$4+3*L$4*M15)+I15 -> 0 | S15: =F$3*(J15*(0.001*L15*1.3)^2*PI()/4) -> 0 | T15: =IF(L15=0,0,(Q15+R15+S15)/J15) -> 0 | U15: =Q15+R15+S15 -> 0 | V15: =U15*F$6 -> 0
A16: 6 | J16: =(C16-D16)*IF(F$7=1,1,0.3049) -> 0 | K16: =IF(E16=0,0,(D16-E16)*IF(F$7=1,1,0.3049)) -> 0 | L16: =IF(F16=0,0,IF((G16=1),HLOOKUP(F16,B$65:F$66,2),HLOOKUP(F16,H$65:L$66,2))) -> 0 | M16: =IF(J16=0,0,J16-L$7+0.3*F16/1000+0.3) -> 0 | N16: =(IF(L16=0,0,IF(L16<1501,VLOOKUP(L16+M16,C$70:D$118,2),VLOOKUP(L16+M16,E$70:F$114,2))+(L$7-0.15)*I$5)*I$3*I$4*(100-F$5)/100) -> 0 | O16: =(((L16/1000)^2*PI()/4*F16/1000)-PI()/4*(F16/1000)^2*L16/1000+L16/1000)*F$4 -> 0 | P16: =IF(L16=0,0,I$6*I$3*I$4) -> 0 | Q16: =H16+N16+O16+P16 -> 0 | R16: =(L16=1200)*(15*L$4+L$4*M16)+(L16=1500)*(20*L$4+1.3*L$4*M16)+(L16=1800)*(30*L$4+1.5*L$4*M16)+(L16=2400)*(40*L$4+2*L$4*M16)+(L16=3000)*(50*L$4+2.5*L$4*M16)+(L16=3600)*(60*L$4+3*L$4*M16)+I16 -> 0 | S16: =F$3*(J16*(0.001*L16*1.3)^2*PI()/4) -> 0 | T16: =IF(L16=0,0,(Q16+R16+S16)/J16) -> 0 | U16: =Q16+R16+S16 -> 0 | V16: =U16*F$6 -> 0
A17: 7 | J17: =(C17-D17)*IF(F$7=1,1,0.3049) -> 0 | K17: =IF(E17=0,0,(D17-E17)*IF(F$7=1,1,0.3049)) -> 0 | L17: =IF(F17=0,0,IF((G17=1),HLOOKUP(F17,B$65:F$66,2),HLOOKUP(F17,H$65:L$66,2))) -> 0 | M17: =IF(J17=0,0,J17-L$7+0.3*F17/1000+0.3) -> 0 | N17: =(IF(L17=0,0,IF(L17<1501,VLOOKUP(L17+M17,C$70:D$118,2),VLOOKUP(L17+M17,E$70:F$114,2))+(L$7-0.15)*I$5)*I$3*I$4*(100-F$5)/100) -> 0 | O17: =(((L17/1000)^2*PI()/4*F17/1000)-PI()/4*(F17/1000)^2*L17/1000+L17/1000)*F$4 -> 0 | P17: =IF(L17=0,0,I$6*I$3*I$4) -> 0 | Q17: =H17+N17+O17+P17 -> 0 | R17: =(L17=1200)*(15*L$4+L$4*M17)+(L17=1500)*(20*L$4+1.3*L$4*M17)+(L17=1800)*(30*L$4+1.5*L$4*M17)+(L17=2400)*(40*L$4+2*L$4*M17)+(L17=3000)*(50*L$4+2.5*L$4*M17)+(L17=3600)*(60*L$4+3*L$4*M17)+I17 -> 0 | S17: =F$3*(J17*(0.001*L17*1.3)^2*PI()/4) -> 0 | T17: =IF(L17=0,0,(Q17+R17+S17)/J17) -> 0 | U17: =Q17+R17+S17 -> 0 | V17: =U17*F$6 -> 0
A18: 8 | J18: =(C18-D18)*IF(F$7=1,1,0.3049) -> 0 | K18: =IF(E18=0,0,(D18-E18)*IF(F$7=1,1,0.3049)) -> 0 | L18: =IF(F18=0,0,IF((G18=1),HLOOKUP(F18,B$65:F$66,2),HLOOKUP(F18,H$65:L$66,2))) -> 0 | M18: =IF(J18=0,0,J18-L$7+0.3*F18/1000+0.3) -> 0 | N18: =(IF(L18=0,0,IF(L18<1501,VLOOKUP(L18+M18,C$70:D$118,2),VLOOKUP(L18+M18,E$70:F$114,2))+(L$7-0.15)*I$5)*I$3*I$4*(100-F$5)/100) -> 0 | O18: =(((L18/1000)^2*PI()/4*F18/1000)-PI()/4*(F18/1000)^2*L18/1000+L18/1000)*F$4 -> 0 | P18: =IF(L18=0,0,I$6*I$3*I$4) -> 0 | Q18: =H18+N18+O18+P18 -> 0 | R18: =(L18=1200)*(15*L$4+L$4*M18)+(L18=1500)*(20*L$4+1.3*L$4*M18)+(L18=1800)*(30*L$4+1.5*L$4*M18)+(L18=2400)*(40*L$4+2*L$4*M18)+(L18=3000)*(50*L$4+2.5*L$4*M18)+(L18=3600)*(60*L$4+3*L$4*M18)+I18 -> 0 | S18: =F$3*(J18*(0.001*L18*1.3)^2*PI()/4) -> 0 | T18: =IF(L18=0,0,(Q18+R18+S18)/J18) -> 0 | U18: =Q18+R18+S18 -> 0 | V18: =U18*F$6 -> 0
A19: 9 | J19: =(C19-D19)*IF(F$7=1,1,0.3049) -> 0 | K19: =IF(E19=0,0,(D19-E19)*IF(F$7=1,1,0.3049)) -> 0 | L19: =IF(F19=0,0,IF((G19=1),HLOOKUP(F19,B$65:F$66,2),HLOOKUP(F19,H$65:L$66,2))) -> 0 | M19: =IF(J19=0,0,J19-L$7+0.3*F19/1000+0.3) -> 0 | N19: =(IF(L19=0,0,IF(L19<1501,VLOOKUP(L19+M19,C$70:D$118,2),VLOOKUP(L19+M19,E$70:F$114,2))+(L$7-0.15)*I$5)*I$3*I$4*(100-F$5)/100) -> 0 | O19: =(((L19/1000)^2*PI()/4*F19/1000)-PI()/4*(F19/1000)^2*L19/1000+L19/1000)*F$4 -> 0 | P19: =IF(L19=0,0,I$6*I$3*I$4) -> 0 | Q19: =H19+N19+O19+P19 -> 0 | R19: =(L19=1200)*(15*L$4+L$4*M19)+(L19=1500)*(20*L$4+1.3*L$4*M19)+(L19=1800)*(30*L$4+1.5*L$4*M19)+(L19=2400)*(40*L$4+2*L$4*M19)+(L19=3000)*(50*L$4+2.5*L$4*M19)+(L19=3600)*(60*L$4+3*L$4*M19)+I19 -> 0 | S19: =F$3*(J19*(0.001*L19*1.3)^2*PI()/4) -> 0 | T19: =IF(L19=0,0,(Q19+R19+S19)/J19) -> 0 | U19: =Q19+R19+S19 -> 0 | V19: =U19*F$6 -> 0
A20: 10 | J20: =(C20-D20)*IF(F$7=1,1,0.3049) -> 0 | K20: =IF(E20=0,0,(D20-E20)*IF(F$7=1,1,0.3049)) -> 0 | L20: =IF(F20=0,0,IF((G20=1),HLOOKUP(F20,B$65:F$66,2),HLOOKUP(F20,H$65:L$66,2))) -> 0 | M20: =IF(J20=0,0,J20-L$7+0.3*F20/1000+0.3) -> 0 | N20: =(IF(L20=0,0,IF(L20<1501,VLOOKUP(L20+M20,C$70:D$118,2),VLOOKUP(L20+M20,E$70:F$114,2))+(L$7-0.15)*I$5)*I$3*I$4*(100-F$5)/100) -> 0 | O20: =(((L20/1000)^2*PI()/4*F20/1000)-PI()/4*(F20/1000)^2*L20/1000+L20/1000)*F$4 -> 0 | P20: =IF(L20=0,0,I$6*I$3*I$4) -> 0 | Q20: =H20+N20+O20+P20 -> 0 | R20: =(L20=1200)*(15*L$4+L$4*M20)+(L20=1500)*(20*L$4+1.3*L$4*M20)+(L20=1800)*(30*L$4+1.5*L$4*M20)+(L20=2400)*(40*L$4+2*L$4*M20)+(L20=3000)*(50*L$4+2.5*L$4*M20)+(L20=3600)*(60*L$4+3*L$4*M20)+I20 -> 0 | S20: =F$3*(J20*(0.001*L20*1.3)^2*PI()/4) -> 0 | T20: =IF(L20=0,0,(Q20+R20+S20)/J20) -> 0 | U20: =Q20+R20+S20 -> 0 | V20: =U20*F$6 -> 0
A21: 11 | J21: =(C21-D21)*IF(F$7=1,1,0.3049) -> 0 | K21: =IF(E21=0,0,(D21-E21)*IF(F$7=1,1,0.3049)) -> 0 | L21: =IF(F21=0,0,IF((G21=1),HLOOKUP(F21,B$65:F$66,2),HLOOKUP(F21,H$65:L$66,2))) -> 0 | M21: =IF(J21=0,0,J21-L$7+0.3*F21/1000+0.3) -> 0 | N21: =(IF(L21=0,0,IF(L21<1501,VLOOKUP(L21+M21,C$70:D$118,2),VLOOKUP(L21+M21,E$70:F$114,2))+(L$7-0.15)*I$5)*I$3*I$4*(100-F$5)/100) -> 0 | O21: =(((L21/1000)^2*PI()/4*F21/1000)-PI()/4*(F21/1000)^2*L21/1000+L21/1000)*F$4 -> 0 | P21: =IF(L21=0,0,I$6*I$3*I$4) -> 0 | Q21: =H21+N21+O21+P21 -> 0 | R21: =(L21=1200)*(15*L$4+L$4*M21)+(L21=1500)*(20*L$4+1.3*L$4*M21)+(L21=1800)*(30*L$4+1.5*L$4*M21)+(L21=2400)*(40*L$4+2*L$4*M21)+(L21=3000)*(50*L$4+2.5*L$4*M21)+(L21=3600)*(60*L$4+3*L$4*M21)+I21 -> 0 | S21: =F$3*(J21*(0.001*L21*1.3)^2*PI()/4) -> 0 | T21: =IF(L21=0,0,(Q21+R21+S21)/J21) -> 0 | U21: =Q21+R21+S21 -> 0 | V21: =U21*F$6 -> 0
A22: 12 | J22: =(C22-D22)*IF(F$7=1,1,0.3049) -> 0 | K22: =IF(E22=0,0,(D22-E22)*IF(F$7=1,1,0.3049)) -> 0 | L22: =IF(F22=0,0,IF((G22=1),HLOOKUP(F22,B$65:F$66,2),HLOOKUP(F22,H$65:L$66,2))) -> 0 | M22: =IF(J22=0,0,J22-L$7+0.3*F22/1000+0.3) -> 0 | N22: =(IF(L22=0,0,IF(L22<1501,VLOOKUP(L22+M22,C$70:D$118,2),VLOOKUP(L22+M22,E$70:F$114,2))+(L$7-0.15)*I$5)*I$3*I$4*(100-F$5)/100) -> 0 | O22: =(((L22/1000)^2*PI()/4*F22/1000)-PI()/4*(F22/1000)^2*L22/1000+L22/1000)*F$4 -> 0 | P22: =IF(L22=0,0,I$6*I$3*I$4) -> 0 | Q22: =H22+N22+O22+P22 -> 0 | R22: =(L22=1200)*(15*L$4+L$4*M22)+(L22=1500)*(20*L$4+1.3*L$4*M22)+(L22=1800)*(30*L$4+1.5*L$4*M22)+(L22=2400)*(40*L$4+2*L$4*M22)+(L22=3000)*(50*L$4+2.5*L$4*M22)+(L22=3600)*(60*L$4+3*L$4*M22)+I22 -> 0 | S22: =F$3*(J22*(0.001*L22*1.3)^2*PI()/4) -> 0 | T22: =IF(L22=0,0,(Q22+R22+S22)/J22) -> 0 | U22: =Q22+R22+S22 -> 0 | V22: =U22*F$6 -> 0
... A46: 36 | J46: =(C46-D46)*IF(F$7=1,1,0.3049) -> 0 | K46: =IF(E46=0,0,(D46-E46)*IF(F$7=1,1,0.3049)) -> 0 | L46: =IF(F46=0,0,IF((G46=1),HLOOKUP(F46,B$65:F$66,2),HLOOKUP(F46,H$65:L$66,2))) -> 0 | M46: =IF(J46=0,0,J46-L$7+0.3*F46/1000+0.3) -> 0 | N46: =(IF(L46=0,0,IF(L46<1501,VLOOKUP(L46+M46,C$70:D$118,2),VLOOKUP(L46+M46,E$70:F$114,2))+(L$7-0.15)*I$5)*I$3*I$4*(100-F$5)/100) -> 0 | O46: =(((L46/1000)^2*PI()/4*F46/1000)-PI()/4*(F46/1000)^2*L46/1000+L46/1000)*F$4 -> 0 | P46: =IF(L46=0,0,I$6*I$3*I$4) -> 0 | Q46: =H46+N46+O46+P46 -> 0 | R46: =(L46=1200)*(15*L$4+L$4*M46)+(L46=1500)*(20*L$4+1.3*L$4*M46)+(L46=1800)*(30*L$4+1.5*L$4*M46)+(L46=2400)*(40*L$4+2*L$4*M46)+(L46=3000)*(50*L$4+2.5*L$4*M46)+(L46=3600)*(60*L$4+3*L$4*M46)+I46 -> 0 | S46: =F$3*(J46*(0.001*L46*1.3)^2*PI()/4) -> 0 | T46: =IF(L46=0,0,(Q46+R46+S46)/J46) -> 0 | U46: =Q46+R46+S46 -> 0 | V46: =U46*F$6 -> 0
A48: MANHOLE TOTALS | H48: =SUM(H9:H46) -> 0 | I48: =SUM(I9:I46) -> 0 | N48: =SUM(N11:N46) -> 0 | O48: =SUM(O11:O46) -> 0 | P48: =SUM(P11:P46) -> 0 | Q48: =SUM(Q11:Q46) -> 0 | R48: =SUM(R11:R46) -> 0 | S48: =SUM(S11:S46) -> 0 | U48: =SUM(U11:U46) -> 0 | V48: =SUM(V11:V46) -> 0
B51: CATCHBASINS
B52: ITEMS | C52: QNTY | D52: WALL" | E52: DPTHm | F52: $GT ea | G52: $/ADDMAT | H52: $/AD L&E | I52: $PRECST | J52: $CONC | K52: $FR&CV | L52: $MATRL | M52: $LAB&EQ | N52: $TRKNG | O52: $ EACH | P52: TOTAL $ | Q52: $ SALE/ | S52: TOTALS | T52: $COST | U52: $MARGIN | V52: $SALE
A53: 1 | B53: SINGLE C.B.'S | D53: 4 | E53: 2.2 | F53: 0 | G53: 0 | H53: 0 | I53: =(IF(D53=4,F$115,F$116)*L6*(E53-L7)+F53*I3*I$4+(L$7-0.15)*I$5)*C53 -> 0 | J53: =C53*0.5*F$4 -> 0 | K53: =C53*I$7*I$3*I$4 -> 0 | L53: =G53*C53+I53+J53+K53 -> 0 | M53: =C53*(C$59+H53) -> 0 | N53: =C53*E53*1*F$3 -> 0 | O53: =IF(C53=0,0,(L53+M53+N53)/C53) -> 0 | P53: =L53+M53+N53 -> 0 | Q53: =O53*F$6 -> 0
A54: 2 | B54: DOUBLE C.B.'S | D54: 4 | E54: 2.2 | F54: 0 | G54: 0 | H54: 0 | I54: =(F119*L6*(E54-L7)+F54*I3*I4+(L7-0.15)*I5*2)*C54 -> 0 | J54: =C54*1*F$4 -> 0 | K54: =C54*I$7*2*I$3*I$4 -> 0 | L54: =G54*C54+I54+J54+K54 -> 0 | M54: =C54*(C$60+H54) -> 0 | N54: =C54*E54*1.8*F$3 -> 0 | O54: =IF(C54=0,0,(L54+M54+N54)/C54) -> 0 | P54: =L54+M54+N54 -> 0 | Q54: =O54*F$6 -> 0 | S54: MATRLS | T54: =Q48+L57 -> 0 | U54: =(F6-1)*T54 -> 0 | V54: =T54+U54 -> 0
A55: 3 | B55: DITCH INLT CB'S | D55: 4 | E55: 2.2 | F55: 0 | G55: 0 | H55: 0 | I55: =(F117*L$6*(E55-L$7)+F55*I$3*I$4+(L7-0.15)*I$5)*C55 -> 0 | J55: =C55*0.5*F$4 -> 0 | K55: =C55*(F59*L6) -> 0 | L55: =G55*C55+I55+J55+K55 -> 0 | M55: =C55*(C$61+H55) -> 0 | N55: =C55*E55*1*F$3 -> 0 | O55: =IF(C55=0,0,(L55+M55+N55)/C55) -> 0 | P55: =L55+M55+N55 -> 0 | Q55: =O55*F$6 -> 0 | S55: L&E | T55: =R48+M57 -> 0 | U55: =(F6-1)*T55 -> 0 | V55: =T55+U55 -> 0
A56: 4 | B56: DDITCH INLT CB'S | D56: 4 | E56: 2.2 | F56: 0 | G56: 0 | H56: 0 | I56: =(F118*L$6*(E56-L$7)+F56*I$3*I$4+(L7-0.15)*I$5)*C56 -> 0 | J56: =C56*1*F$4 -> 0 | K56: =C56*(F60*L6) -> 0 | L56: =G56*C56+I56+J56+K56 -> 0 | M56: =C56*(C$62+H56) -> 0 | N56: =C56*E56*1.8*F$3 -> 0 | O56: =IF(C56=0,0,(L56+M56+N56)/C56) -> 0 | P56: =L56+M56+N56 -> 0 | Q56: =O56*F$6 -> 0 | S56: TRUCKING | T56: =S48+N57 -> 0 | U56: =(F6-1)*T56 -> 0 | V56: =T56+U56 -> 0
A57: CATCHBASIN TOTALS | C57: =SUM(C53:C56) -> 0 | G57: =SUM(G53:G56) -> 0 | H57: =SUM(H53:H56) -> 0 | I57: =SUM(I53:I56) -> 0 | J57: =SUM(J53:J56) -> 0 | K57: =SUM(K53:K56) -> 0 | L57: =SUM(L53:L56) -> 0 | M57: =SUM(M53:M56) -> 0 | N57: =SUM(N53:N56) -> 0 | P57: =SUM(P53:P56) -> 0 | Q57: =SUM(Q53:Q56) -> 0 | S57: BID PRICE | T57: =SUM(T54:T56) -> 0 | U57: =(F6-1)*T57 -> 0 | V57: =T57+U57 -> 0
B59: LABOR SCB | C59: 200 | E59: DICB F&C $ | F59: 465
B60: LABOR DCB | C60: 250 | E60: DDICB F&C $ | F60: 715
B61: LABOR DICB | C61: 220
B62: LABOR DDICB | C62: 280
A64: LOOKUP TABLE FOR MANHOLE SIZE
A65: PipeIDstr | B65: 50 | C65: 601 | D65: 826 | E65: 1051 | F65: 1501 | G65: PipeIDang | H65: 50 | I65: 451 | J65: 601 | K65: 826 | L65: 1051
A66: MH dia | B66: 1200 | C66: 1500 | D66: 1800 | E66: 2400 | F66: =NA() -> #N/A | G66: MHdia mm | H66: 1200 | I66: 1500 | J66: 1800 | K66: 2400 | L66: =NA() -> #N/A
A69: LOOKUP TABLE | C69: MH Prices June 2022 | G69: NOTE: Paste copy in boxed area of MH Pricer
C70: 1200 | D70: #N/A | E70: 1800 | F70: #N/A | G70: to this boxed area. USING "PASTE SPECIAL"
C71: 1201 | D71: 2254.681 | E71: 1801.67 | F71: 6780.1253 | G71: AND OPTING FOR TEXT ONLY.
C72: 1201.33 | D72: 2603.3108 | E72: 1802 | F72: 7531.5512
...

Sheet SEWERS (1)
A1: TOPSITE CONTRACTING LIMITED - SEWER RUNS ESTIMATE - 2022
A3: JOB: | C3: Min Trench Width m | F3: 1.2 | G3: $/ImpT Stone | I3: 22 | K3: 100PVC$/m | M3: 12 | N3: %Efficiency | P3: 100 | U3: ProvTax | V3: 1
C4: Pipe Cover m | F4: 0.3 | G4: $/Mt Stone | I4: 35 | K4: 150PVC$/m | M4: 24 | N4: M/Imp (1/0) | P4: 1 | U4: FedTax | V4: 1
A5: DATE: | C5: M-Fin Grade | F5: 0 | G5: $/ImpTn Gran | I5: 10 | K5: 200PVC$/m | M5: 34 | N5: Margin Fctr | P5: 1.1 | U5: CP Fctr | V5: =(1-P8/100)*V4*V3 -> 0.6
C6: Daycost $/Day | F6: 9000 | G6: $/Mt Gran | I6: 30 | K6: 250PVC$/m | M6: 51 | N6: OpenCutFctr | P6: 0.9 | U6: PC Fctr | V6: =(1-S4/100)*V3 -> 1
C7: $Xtra/Day | F7: 300 | G7: $Trucking/cm | I7: 10 | K7: 300PVC$/m | M7: 73 | N7: DualTrSep m | P7: 0.8
C8: Prdtn M/Day | F8: 65 | K8: 375PVC$/m | M8: 97 | N8: ConcPipe% | P8: 40 | AD8: REVISED: | AE8: 44859
K9: 450PVC$/m | M9: 153 | N9: TrenchClear m | P9: 0.3 | AD9: PRINTED: | AE9: =TODAY() -> 46143
A11: Item | B11: RUN | C11: Length | D11: PIPE | E11: TYPE | F11: V/|| | G11: Depth | H11: Add | I11: Add | J11: OD | K11: Ground | M11: Trench | N11: %Prdtn | O11: DAY | P11: EXCAV | Q11: CALC | R11: PROD | S11: LAB&EQ | T11: PIPE | U11: TOTAL | V11: TOTAL $ | W11: TOTAL $ | X11: TOTAL $ | Y11: TOTAL $ | Z11: TOTAL $ | AA11: COST | AB11: TOTAL | AC11: Excav | AD11: Trench | AE11: TOTAL
A12: # | C12: =IF(P4=1,"METER","FEET") -> METER | D12: mm | E12: Class | F12: O/OO | G12: m | H12: Matrls $ | I12: L&E $ | J12: m | K12: Cover m | L12: calc. | M12: Widthm | N12: Effcnt | O12: COST | P12: cm/m | Q12: PROD | R12: m/day | S12: $/m | T12: $/m | U12: $ PIPE | V12: Crshd St | W12: Granular | X12: Materials | Y12: Lab&Eq | Z12: TRUCKING | AA12: =IF(P4=1,"$/METER","$/FOOT") -> $/METER | AB12: COST | AC12: tcm | AD12: Lngth m | AE12: SALE
A14: 1 | J14: =0.00125*D14 -> 0 | K14: =IF(F14<2,F$4,G14-(1.12*D14*0.001)-F$5) -> 0.3 | L14: =(F14=2.1)*IF(G14<3.1,J14+3*S$6,J14+0.6+2*S$6+G14*0.05)+(F14=2.2)*IF(G14<3.1,J14+1.5*S$6+P$7/2,J14+0.3+S$6+G14*0.025) -> 0 | M14: =(F14=1.1)*IF((J14+2*P$9)<F$3,F$3,J14+2*P$9)+(F14=1.2)*(J14+P$9+P$7/2)+(F14=2.1)*IF(L14<F$3,F$3,L14)+(F14=2.2)*L14 -> 0 | N14: =P$3 -> 100 | O14: =F$6+HLOOKUP(G14,J$86:U$87,2)*F$7 -> 9000 | P14: =(M14*G14+(G14>1.219)*(F14=1.1)*(G14-1.22)^2*P$6+(F14=1.2)*(G14-1.22)^2/2*P$6)*(C14>0) -> 0 | Q14: =IF(C14=0,0,IF(TRUNC(F14)=1,HLOOKUP(G14,C$80:AC$81,2),HLOOKUP(G14,C$82:AC$83,2))*N14/100/IF((F14-TRUNC(F14))=0.2,P14*2,P14)) -> 0 | R14: =IF(Q14>F$8,F$8,Q14)*((F14=1.1)*1+(F14=1.2)*0.95+(F14=2.1)*0.95+(F14=2.2)*1) -> 0 | S14: =IF(C14=0,0,IF(OR(F14=1.2,F14=2.2),O14/R14/2,O14/R14)) -> 0 | T14: =IF(TRUNC(E14)>1,HLOOKUP(D14,C$86:I$87,2),IF(D14<=980,HLOOKUP(D14+10*(E14-1),B$74:AG$75,2),HLOOKUP(D14+10*(E14-1),B$76:AG$77,2))) -> #VALUE! | U14: =(IF(C14=0,0,IF(TRUNC(E14)=1,T14*C14*V$5,T14*C14*V$3)))*IF(P$4=1,1,1/3.28) -> 0 | V14: =((M14*0.6*J14+0.005)-PI()*J14^2/8)*C14*2*I$4*IF(P$4=1,1,1/3.28) -> 0 | W14: =(((0.5*J14+K14)*M14)-(PI()*J14^2/8))*C14*2*I$6*IF(P$4=1,1,1/3.28) -> 0 | X14: =H14+U14+V14+W14 -> 0 | Y14: =I14+S14*C14*IF(P$4=1,1,1/3.28) -> 0 | Z14: =((V14/I$4+W14/I$6)/2+PI()*J14^2/4*C14*IF(P$4=1,1,1/3.28))*I$7 -> 0 | AA14: =ROUND(IF(C14=0,0,(X14+Y14+Z14)/C14),2) -> 0 | AB14: =X14+Y14+Z14 -> 0 | AC14: =P14*C14*IF(P$4=1,1,1/3.28) -> 0 | AD14: =IF(C14=0,0,C14/((F14-TRUNC(F14))*10)*IF(P$4=1,1,1/3.28)) -> 0 | AE14: =AB14*$P$5 -> 0
A15: 2 | J15: =0.00125*D15 -> 0 | K15: =IF(F15<2,F$4,G15-(1.12*D15*0.001)-F$5) -> 0.3 | L15: =(F15=2.1)*IF(G15<3.1,J15+3*S$6,J15+0.6+2*S$6+G15*0.05)+(F15=2.2)*IF(G15<3.1,J15+1.5*S$6+P$7/2,J15+0.3+S$6+G15*0.025) -> 0 | M15: =(F15=1.1)*IF((J15+2*P$9)<F$3,F$3,J15+2*P$9)+(F15=1.2)*(J15+P$9+P$7/2)+(F15=2.1)*IF(L15<F$3,F$3,L15)+(F15=2.2)*L15 -> 0 | N15: =P$3 -> 100 | O15: =F$6+HLOOKUP(G15,J$86:U$87,2)*F$7 -> 9000 | P15: =(M15*G15+(G15>1.219)*(F15=1.1)*(G15-1.22)^2*P$6+(F15=1.2)*(G15-1.22)^2/2*P$6)*(C15>0) -> 0 | Q15: =IF(C15=0,0,IF(TRUNC(F15)=1,HLOOKUP(G15,C$80:AC$81,2),HLOOKUP(G15,C$82:AC$83,2))*N15/100/IF((F15-TRUNC(F15))=0.2,P15*2,P15)) -> 0 | R15: =IF(Q15>F$8,F$8,Q15)*((F15=1.1)*1+(F15=1.2)*0.95+(F15=2.1)*0.95+(F15=2.2)*1) -> 0 | S15: =IF(C15=0,0,IF(OR(F15=1.2,F15=2.2),O15/R15/2,O15/R15)) -> 0 | T15: =IF(TRUNC(E15)>1,HLOOKUP(D15,C$86:I$87,2),IF(D15<=980,HLOOKUP(D15+10*(E15-1),B$74:AG$75,2),HLOOKUP(D15+10*(E15-1),B$76:AG$77,2))) -> #VALUE! | U15: =(IF(C15=0,0,IF(TRUNC(E15)=1,T15*C15*V$5,T15*C15*V$3)))*IF(P$4=1,1,1/3.28) -> 0 | V15: =((M15*0.6*J15+0.005)-PI()*J15^2/8)*C15*2*I$4*IF(P$4=1,1,1/3.28) -> 0 | W15: =(((0.5*J15+K15)*M15)-(PI()*J15^2/8))*C15*2*I$6*IF(P$4=1,1,1/3.28) -> 0 | X15: =H15+U15+V15+W15 -> 0 | Y15: =I15+S15*C15*IF(P$4=1,1,1/3.28) -> 0 | Z15: =((V15/I$4+W15/I$6)/2+PI()*J15^2/4*C15*IF(P$4=1,1,1/3.28))*I$7 -> 0 | AA15: =ROUND(IF(C15=0,0,(X15+Y15+Z15)/C15),2) -> 0 | AB15: =X15+Y15+Z15 -> 0 | AC15: =P15*C15*IF(P$4=1,1,1/3.28) -> 0 | AD15: =IF(C15=0,0,C15/((F15-TRUNC(F15))*10)*IF(P$4=1,1,1/3.28)) -> 0 | AE15: =AB15*$P$5 -> 0
A16: 3 | J16: =0.00125*D16 -> 0 | K16: =IF(F16<2,F$4,G16-(1.12*D16*0.001)-F$5) -> 0.3 | L16: =(F16=2.1)*IF(G16<3.1,J16+3*S$6,J16+0.6+2*S$6+G16*0.05)+(F16=2.2)*IF(G16<3.1,J16+1.5*S$6+P$7/2,J16+0.3+S$6+G16*0.025) -> 0 | M16: =(F16=1.1)*IF((J16+2*P$9)<F$3,F$3,J16+2*P$9)+(F16=1.2)*(J16+P$9+P$7/2)+(F16=2.1)*IF(L16<F$3,F$3,L16)+(F16=2.2)*L16 -> 0 | N16: =P$3 -> 100 | O16: =F$6+HLOOKUP(G16,J$86:U$87,2)*F$7 -> 9000 | P16: =(M16*G16+(G16>1.219)*(F16=1.1)*(G16-1.22)^2*P$6+(F16=1.2)*(G16-1.22)^2/2*P$6)*(C16>0) -> 0 | Q16: =IF(C16=0,0,IF(TRUNC(F16)=1,HLOOKUP(G16,C$80:AC$81,2),HLOOKUP(G16,C$82:AC$83,2))*N16/100/IF((F16-TRUNC(F16))=0.2,P16*2,P16)) -> 0 | R16: =IF(Q16>F$8,F$8,Q16)*((F16=1.1)*1+(F16=1.2)*0.95+(F16=2.1)*0.95+(F16=2.2)*1) -> 0 | S16: =IF(C16=0,0,IF(OR(F16=1.2,F16=2.2),O16/R16/2,O16/R16)) -> 0 | T16: =IF(TRUNC(E16)>1,HLOOKUP(D16,C$86:I$87,2),IF(D16<=980,HLOOKUP(D16+10*(E16-1),B$74:AG$75,2),HLOOKUP(D16+10*(E16-1),B$76:AG$77,2))) -> #VALUE! | U16: =(IF(C16=0,0,IF(TRUNC(E16)=1,T16*C16*V$5,T16*C16*V$3)))*IF(P$4=1,1,1/3.28) -> 0 | V16: =((M16*0.6*J16+0.005)-PI()*J16^2/8)*C16*2*I$4*IF(P$4=1,1,1/3.28) -> 0 | W16: =(((0.5*J16+K16)*M16)-(PI()*J16^2/8))*C16*2*I$6*IF(P$4=1,1,1/3.28) -> 0 | X16: =H16+U16+V16+W16 -> 0 | Y16: =I16+S16*C16*IF(P$4=1,1,1/3.28) -> 0 | Z16: =((V16/I$4+W16/I$6)/2+PI()*J16^2/4*C16*IF(P$4=1,1,1/3.28))*I$7 -> 0 | AA16: =ROUND(IF(C16=0,0,(X16+Y16+Z16)/C16),2) -> 0 | AB16: =X16+Y16+Z16 -> 0 | AC16: =P16*C16*IF(P$4=1,1,1/3.28) -> 0 | AD16: =IF(C16=0,0,C16/((F16-TRUNC(F16))*10)*IF(P$4=1,1,1/3.28)) -> 0 | AE16: =AB16*$P$5 -> 0
A17: 4 | J17: =0.00125*D17 -> 0 | K17: =IF(F17<2,F$4,G17-(1.12*D17*0.001)-F$5) -> 0.3 | L17: =(F17=2.1)*IF(G17<3.1,J17+3*S$6,J17+0.6+2*S$6+G17*0.05)+(F17=2.2)*IF(G17<3.1,J17+1.5*S$6+P$7/2,J17+0.3+S$6+G17*0.025) -> 0 | M17: =(F17=1.1)*IF((J17+2*P$9)<F$3,F$3,J17+2*P$9)+(F17=1.2)*(J17+P$9+P$7/2)+(F17=2.1)*IF(L17<F$3,F$3,L17)+(F17=2.2)*L17 -> 0 | N17: =P$3 -> 100 | O17: =F$6+HLOOKUP(G17,J$86:U$87,2)*F$7 -> 9000 | P17: =(M17*G17+(G17>1.219)*(F17=1.1)*(G17-1.22)^2*P$6+(F17=1.2)*(G17-1.22)^2/2*P$6)*(C17>0) -> 0 | Q17: =IF(C17=0,0,IF(TRUNC(F17)=1,HLOOKUP(G17,C$80:AC$81,2),HLOOKUP(G17,C$82:AC$83,2))*N17/100/IF((F17-TRUNC(F17))=0.2,P17*2,P17)) -> 0 | R17: =IF(Q17>F$8,F$8,Q17)*((F17=1.1)*1+(F17=1.2)*0.95+(F17=2.1)*0.95+(F17=2.2)*1) -> 0 | S17: =IF(C17=0,0,IF(OR(F17=1.2,F17=2.2),O17/R17/2,O17/R17)) -> 0 | T17: =IF(TRUNC(E17)>1,HLOOKUP(D17,C$86:I$87,2),IF(D17<=980,HLOOKUP(D17+10*(E17-1),B$74:AG$75,2),HLOOKUP(D17+10*(E17-1),B$76:AG$77,2))) -> #VALUE! | U17: =(IF(C17=0,0,IF(TRUNC(E17)=1,T17*C17*V$5,T17*C17*V$3)))*IF(P$4=1,1,1/3.28) -> 0 | V17: =((M17*0.6*J17+0.005)-PI()*J17^2/8)*C17*2*I$4*IF(P$4=1,1,1/3.28) -> 0 | W17: =(((0.5*J17+K17)*M17)-(PI()*J17^2/8))*C17*2*I$6*IF(P$4=1,1,1/3.28) -> 0 | X17: =H17+U17+V17+W17 -> 0 | Y17: =I17+S17*C17*IF(P$4=1,1,1/3.28) -> 0 | Z17: =((V17/I$4+W17/I$6)/2+PI()*J17^2/4*C17*IF(P$4=1,1,1/3.28))*I$7 -> 0 | AA17: =ROUND(IF(C17=0,0,(X17+Y17+Z17)/C17),2) -> 0 | AB17: =X17+Y17+Z17 -> 0 | AC17: =P17*C17*IF(P$4=1,1,1/3.28) -> 0 | AD17: =IF(C17=0,0,C17/((F17-TRUNC(F17))*10)*IF(P$4=1,1,1/3.28)) -> 0 | AE17: =AB17*$P$5 -> 0
A18: 5 | J18: =0.00125*D18 -> 0 | K18: =IF(F18<2,F$4,G18-(1.12*D18*0.001)-F$5) -> 0.3 | L18: =(F18=2.1)*IF(G18<3.1,J18+3*S$6,J18+0.6+2*S$6+G18*0.05)+(F18=2.2)*IF(G18<3.1,J18+1.5*S$6+P$7/2,J18+0.3+S$6+G18*0.025) -> 0 | M18: =(F18=1.1)*IF((J18+2*P$9)<F$3,F$3,J18+2*P$9)+(F18=1.2)*(J18+P$9+P$7/2)+(F18=2.1)*IF(L18<F$3,F$3,L18)+(F18=2.2)*L18 -> 0 | N18: =P$3 -> 100 | O18: =F$6+HLOOKUP(G18,J$86:U$87,2)*F$7 -> 9000 | P18: =(M18*G18+(G18>1.219)*(F18=1.1)*(G18-1.22)^2*P$6+(F18=1.2)*(G18-1.22)^2/2*P$6)*(C18>0) -> 0 | Q18: =IF(C18=0,0,IF(TRUNC(F18)=1,HLOOKUP(G18,C$80:AC$81,2),HLOOKUP(G18,C$82:AC$83,2))*N18/100/IF((F18-TRUNC(F18))=0.2,P18*2,P18)) -> 0 | R18: =IF(Q18>F$8,F$8,Q18)*((F18=1.1)*1+(F18=1.2)*0.95+(F18=2.1)*0.95+(F18=2.2)*1) -> 0 | S18: =IF(C18=0,0,IF(OR(F18=1.2,F18=2.2),O18/R18/2,O18/R18)) -> 0 | T18: =IF(TRUNC(E18)>1,HLOOKUP(D18,C$86:I$87,2),IF(D18<=980,HLOOKUP(D18+10*(E18-1),B$74:AG$75,2),HLOOKUP(D18+10*(E18-1),B$76:AG$77,2))) -> #VALUE! | U18: =(IF(C18=0,0,IF(TRUNC(E18)=1,T18*C18*V$5,T18*C18*V$3)))*IF(P$4=1,1,1/3.28) -> 0 | V18: =((M18*0.6*J18+0.005)-PI()*J18^2/8)*C18*2*I$4*IF(P$4=1,1,1/3.28) -> 0 | W18: =(((0.5*J18+K18)*M18)-(PI()*J18^2/8))*C18*2*I$6*IF(P$4=1,1,1/3.28) -> 0 | X18: =H18+U18+V18+W18 -> 0 | Y18: =I18+S18*C18*IF(P$4=1,1,1/3.28) -> 0 | Z18: =((V18/I$4+W18/I$6)/2+PI()*J18^2/4*C18*IF(P$4=1,1,1/3.28))*I$7 -> 0 | AA18: =ROUND(IF(C18=0,0,(X18+Y18+Z18)/C18),2) -> 0 | AB18: =X18+Y18+Z18 -> 0 | AC18: =P18*C18*IF(P$4=1,1,1/3.28) -> 0 | AD18: =IF(C18=0,0,C18/((F18-TRUNC(F18))*10)*IF(P$4=1,1,1/3.28)) -> 0 | AE18: =AB18*$P$5 -> 0
A19: 6 | J19: =0.00125*D19 -> 0 | K19: =IF(F19<2,F$4,G19-(1.12*D19*0.001)-F$5) -> 0.3 | L19: =(F19=2.1)*IF(G19<3.1,J19+3*S$6,J19+0.6+2*S$6+G19*0.05)+(F19=2.2)*IF(G19<3.1,J19+1.5*S$6+P$7/2,J19+0.3+S$6+G19*0.025) -> 0 | M19: =(F19=1.1)*IF((J19+2*P$9)<F$3,F$3,J19+2*P$9)+(F19=1.2)*(J19+P$9+P$7/2)+(F19=2.1)*IF(L19<F$3,F$3,L19)+(F19=2.2)*L19 -> 0 | N19: =P$3 -> 100 | O19: =F$6+HLOOKUP(G19,J$86:U$87,2)*F$7 -> 9000 | P19: =(M19*G19+(G19>1.219)*(F19=1.1)*(G19-1.22)^2*P$6+(F19=1.2)*(G19-1.22)^2/2*P$6)*(C19>0) -> 0 | Q19: =IF(C19=0,0,IF(TRUNC(F19)=1,HLOOKUP(G19,C$80:AC$81,2),HLOOKUP(G19,C$82:AC$83,2))*N19/100/IF((F19-TRUNC(F19))=0.2,P19*2,P19)) -> 0 | R19: =IF(Q19>F$8,F$8,Q19)*((F19=1.1)*1+(F19=1.2)*0.95+(F19=2.1)*0.95+(F19=2.2)*1) -> 0 | S19: =IF(C19=0,0,IF(OR(F19=1.2,F19=2.2),O19/R19/2,O19/R19)) -> 0 | T19: =IF(TRUNC(E19)>1,HLOOKUP(D19,C$86:I$87,2),IF(D19<=980,HLOOKUP(D19+10*(E19-1),B$74:AG$75,2),HLOOKUP(D19+10*(E19-1),B$76:AG$77,2))) -> #VALUE! | U19: =(IF(C19=0,0,IF(TRUNC(E19)=1,T19*C19*V$5,T19*C19*V$3)))*IF(P$4=1,1,1/3.28) -> 0 | V19: =((M19*0.6*J19+0.005)-PI()*J19^2/8)*C19*2*I$4*IF(P$4=1,1,1/3.28) -> 0 | W19: =(((0.5*J19+K19)*M19)-(PI()*J19^2/8))*C19*2*I$6*IF(P$4=1,1,1/3.28) -> 0 | X19: =H19+U19+V19+W19 -> 0 | Y19: =I19+S19*C19*IF(P$4=1,1,1/3.28) -> 0 | Z19: =((V19/I$4+W19/I$6)/2+PI()*J19^2/4*C19*IF(P$4=1,1,1/3.28))*I$7 -> 0 | AA19: =ROUND(IF(C19=0,0,(X19+Y19+Z19)/C19),2) -> 0 | AB19: =X19+Y19+Z19 -> 0 | AC19: =P19*C19*IF(P$4=1,1,1/3.28) -> 0 | AD19: =IF(C19=0,0,C19/((F19-TRUNC(F19))*10)*IF(P$4=1,1,1/3.28)) -> 0 | AE19: =AB19*$P$5 -> 0
